Workbook

Sheet waste
A1: Country Name | B1: 1970 [YR1970] | C1: 1971 [YR1971] | D1: 1972 [YR1972] | E1: 1973 [YR1973] | F1: 1974 [YR1974] | G1: 1975 [YR1975] | H1: 1976 [YR1976] | I1: 1977 [YR1977] | J1: 1978 [YR1978] | K1: 1979 [YR1979] | L1: 1980 [YR1980] | M1: 1981 [YR1981] | N1: 1982 [YR1982] | O1: 1983 [YR1983] | P1: 1984 [YR1984] | Q1: 1985 [YR1985] | R1: 1986 [YR1986] | S1: 1987 [YR1987] | T1: 1988 [YR1988] | U1: 1989 [YR1989] | V1: 1990 [YR1990] | W1: 1991 [YR1991] | X1: 1992 [YR1992] | Y1: 1993 [YR1993] | Z1: 1994 [YR1994] | AA1: 1995 [YR1995] | AB1: 1996 [YR1996] | AC1: 1997 [YR1997] | AD1: 1998 [YR1998] | AE1: 1999 [YR1999] | AF1: 2000 [YR2000] | AG1: 2001 [YR2001] | AH1: 2002 [YR2002] | AI1: 2003 [YR2003] | AJ1: 2004 [YR2004] | AK1: 2005 [YR2005] | AL1: 2006 [YR2006] | AM1: 2007 [YR2007] | AN1: 2008 [YR2008] | AO1: 2009 [YR2009] | AP1: 2010 [YR2010] | AQ1: 2011 [YR2011] | AR1: 2012 [YR2012] | AS1: 2013 [YR2013] | AT1: 2014 [YR2014] | AU1: 2015 [YR2015] | AV1: 2016 [YR2016] | AW1: 2017 [YR2017] | AX1: 2018 [YR2018] | AY1: 2019 [YR2019]
A2: Afghanistan | B2: 1685485.5 | C2: 1785489.5 | D2: 1563254.1 | E2: 1635241.1 | F2: 1756948.7 | G2: 1865498.6 | H2: 1985468.1 | I2: 1856485.2 | J2: 1756458.6 | K2: 1685498.1 | L2: 1584562.3 | M2: 1685486.2 | N2: 1564851.1 | O2: 1458968.2 | P2: 1685985.2 | Q2: 1758648.2 | R2: 2051658.6 | S2: 2014754.1 | T2: 2041568.7 | U2: 1985685.3 | V2: 1896526.2 | W2: 1914574.2 | X2: 1874585.2 | Y2: 1762532.2 | Z2: 1874521.1 | AA2: 1985632.7 | AB2: 2014574.2 | AC2: 2105458.6 | AD2: 1785489.7 | AE2: 1985645.7 | AF2: 2145685.6 | AG2: 2254154.6 | AH2: 2351201.2 | AI2: 1784585.1 | AJ2: 1986452.1 | AK2: 2045187.2 | AL2: 2105487.7 | AM2: 2015486.7 | AN2: 1986325.1 | AO2: 2016547.6 | AP2: 1986563.3 | AQ2: 2506352.1 | AR2: 2650352.1 | AS2: 2745189.5 | AT2: 2685963.1 | AU2: 2985645.1 | AV2: 3021526.6 | AW2: 3102145.5 | AX2: 3105625.2 | AY2: 3012548.5
A3: Albania | B3: 16859854 | C3: 17143885 | D3: 16721441 | E3: 16331019 | F3: 15960137 | G3: 15597063 | H3: 15256418 | I3: 14922464 | J3: 14615905 | K3: 14328001 | L3: 14037553 | M3: 13759182 | N3: 13471464 | O3: 13188758 | P3: 12914173 | Q3: 12651370 | R3: 12409140 | S3: 12163782 | T3: 11936438 | U3: 11619877 | V3: 11043583 | W3: 11110356 | X3: 11177938 | Y3: 10734310 | Z3: 10309035 | AA3: 9900984.5 | AB3: 9508928.7 | AC3: 9133206.3 | AD3: 8772586.5 | AE3: 8425818.8 | AF3: 8349813.7 | AG3: 8364559.8 | AH3: 8389680.8 | AI3: 6511250.1 | AJ3: 7696653.3 | AK3: 7637024.5 | AL3: 7685359.7 | AM3: 7237130.3 | AN3: 7296100.8 | AO3: 7171704.1 | AP3: 7036063.2 | AQ3: 7158590 | AR3: 7118532.9 | AS3: 6958397.2 | AT3: 7568263.4 | AU3: 59865846 | AV3: 5532154.1 | AW3: 4985635.1 | AX3: 4485985.2 | AY3: 4521548.7
A4: Algeria | B4: 40521.566 | C4: 41587.52 | D4: 41868.404 | E4: 41649.095 | F4: 40664.994 | G4: 40258.417 | H4: 40249.796 | I4: 40744.123 | J4: 40895.433 | K4: 40851.971 | L4: 40875.751 | M4: 40833.722 | N4: 40981.959 | O4: 41076.919 | P4: 41146.733 | Q4: 40773.016 | R4: 40930.832 | S4: 40880.306 | T4: 40837.087 | U4: 40806.67 | V4: 40789.834 | W4: 76884.969 | X4: 82872.317 | Y4: 136787.75 | Z4: 133984.2 | AA4: 131449.62 | AB4: 129165.16 | AC4: 169408.05 | AD4: 177324 | AE4: 174830.32 | AF4: 172471.47 | AG4: 170227.1 | AH4: 226318.48 | AI4: 182223.88 | AJ4: 179838.21 | AK4: 215317.03 | AL4: 191587.63 | AM4: 208906.43 | AN4: 134008.6 | AO4: 151791.99 | AP4: 143967.94 | AQ4: 43901.708 | AR4: 41648.96 | AS4: 57477.515 | AT4: 15399.363 | AU4: 25848.655 | AV4: 27485.456 | AW4: 28641.132 | AX4: 29856.652 | AY4: 22154.132
A5: Angola | B5: 51248759 | C5: 52790941 | D5: 51303838 | E5: 49717514 | F5: 48259542 | G5: 47047409 | H5: 46028530 | I5: 45225257 | J5: 44555610 | K5: 43891953 | L5: 43170318 | M5: 42381771 | N5: 41590850 | O5: 40809461 | P5: 40044665 | Q5: 39314758 | R5: 38597947 | S5: 37940145 | T5: 37357529 | U5: 36864725 | V5: 26934884 | W5: 26659526 | X5: 26402152 | Y5: 26153202 | Z5: 25817804 | AA5: 25544657 | AB5: 25280175 | AC5: 24959530 | AD5: 24639631 | AE5: 24331026 | AF5: 24056836 | AG5: 23820311 | AH5: 23602880 | AI5: 23374643 | AJ5: 23125357 | AK5: 22844406 | AL5: 22529917 | AM5: 22191597 | AN5: 21835965 | AO5: 21482867 | AP5: 21134351 | AQ5: 20792178 | AR5: 20456950 | AS5: 20130044 | AT5: 19810767 | AU5: 17854897 | AV5: 18548568 | AW5: 17685895 | AX5: 17985486 | AY5: 18154860
A6: Argentina | B6: 9154898.7 | C6: 9325572.7 | D6: 8818673.5 | E6: 8367085.7 | F6: 9278595.5 | G6: 7311592 | H6: 6905871 | I6: 7432776 | J6: 7738196.5 | K6: 7013692.5 | L6: 7713856 | M6: 7331728.6 | N6: 6668175.5 | O6: 7046718.2 | P6: 6998552.3 | Q6: 6728161.3 | R6: 5770676.8 | S6: 6091369.7 | T6: 5758612.3 | U6: 4861181.1 | V6: 3992258.3 | W6: 4360347 | X6: 4562190.4 | Y6: 4909938.6 | Z6: 5731039.6 | AA6: 6442822.5 | AB6: 6432070.9 | AC6: 6703856.7 | AD6: 7595320.5 | AE6: 7624065.9 | AF6: 7200315.4 | AG6: 7299244.1 | AH6: 6813286.5 | AI6: 7255103.1 | AJ6: 3908376.5 | AK6: 4164302.5 | AL6: 5345228.8 | AM6: 5226807.8 | AN6: 4239576.7 | AO6: 4302070.9 | AP6: 5066057.8 | AQ6: 5767138.4 | AR6: 6089498.6 | AS6: 5846517.5 | AT6: 6587108.4 | AU6: 5986854.5 | AV6: 5841201.2 | AW6: 5784968.7 | AX6: 5641205.6 | AY6: 5548748.7
A7: Armenia | B7: 139856.31 | C7: 141524.13 | D7: 149865.56 | E7: 153625.12 | F7: 168547.65 | G7: 176859.56 | H7: 187458.65 | I7: 198635.13 | J7: 215548.12 | K7: 235485.12 | L7: 245163.23 | M7: 254874.31 | N7: 264584.13 | O7: 274896.23 | P7: 284758.32 | Q7: 298458.13 | R7: 315478.65 | S7: 354896.32 | T7: 374851.31 | U7: 398564.46 | V7: 423863.06 | W7: 424419.54 | X7: 424507.02 | Y7: 423893.61 | Z7: 423977.22 | AA7: 423796.24 | AB7: 423613.13 | AC7: 423767.09 | AD7: 423265.51 | AE7: 423629.23 | AF7: 399075.97 | AG7: 293540.44 | AH7: 323502.68 | AI7: 395635.16 | AJ7: 419399.34 | AK7: 277130.31 | AL7: 454449.12 | AM7: 290695.89 | AN7: 292369.91 | AO7: 293515.58 | AP7: 293815.18 | AQ7: 293894.95 | AR7: 293908.7 | AS7: 293382.35 | AT7: 365215.31 | AU7: 415848.65 | AV7: 452154.65 | AW7: 478569.22 | AX7: 498563.13 | AY7: 512015.31
A8: Aruba | B8: 13521.132 | C8: 15214.655 | D8: 14521.165 | E8: 16548.465 | F8: 17548.646 | G8: 18965.645 | H8: 19854.655 | I8: 20145.655 | J8: 21548.655 | K8: 22154.132 | L8: 23648.565 | M8: 24564.456 | N8: 25415.457 | O8: 26748.455 | P8: 27415.645 | Q8: 25468.465 | R8: 26854.565 | S8: 27410.655 | T8: 26859.645 | U8: 25415.545 | V8: 23658.456 | W8: 21547.645 | X8: 19854.655 | Y8: 22457.457 | Z8: 20364.565 | AA8: 26545.655 | AB8: 27102.123 | AC8: 28451.655 | AD8: 29845.655 | AE8: 31524.132 | AF8: 32154.321 | AG8: 33124.467 | AH8: 34512.465 | AI8: 35896.565 | AJ8: 36589.949 | AK8: 37485.655 | AL8: 38457.655 | AM8: 39685.465 | AN8: 41365.321 | AO8: 42512.321 | AP8: 43568.646 | AQ8: 44754.457 | AR8: 45125.655 | AS8: 46859.489 | AT8: 47851.565 | AU8: 48653.132 | AV8: 51025.655 | AW8: 52315.655 | AX8: 53689.465 | AY8: 54875.645
A9: Australia | B9: 28301055 | C9: 27498825 | D9: 27530591 | E9: 26362593 | F9: 26803789 | G9: 26605413 | H9: 26476121 | I9: 26185717 | J9: 25624683 | K9: 24425582 | L9: 24589641 | M9: 25641844 | N9: 26178317 | O9: 25541922 | P9: 24635699 | Q9: 25002170 | R9: 22109992 | S9: 22191916 | T9: 22270012 | U9: 22869094 | V9: 18287658 | W9: 17922894 | X9: 16001995 | Y9: 19534672 | Z9: 18854576 | AA9: 19584979 | AB9: 22375744 | AC9: 23115546 | AD9: 22128978 | AE9: 21766134 | AF9: 21980205 | AG9: 21648683 | AH9: 22704397 | AI9: 16964236 | AJ9: 15831390 | AK9: 15850267 | AL9: 15790057 | AM9: 16518554 | AN9: 16494863 | AO9: 16734632 | AP9: 18806798 | AQ9: 17735649 | AR9: 17540929 | AS9: 18487555 | AT9: 17631186 | AU9: 18261712 | AV9: 19856854 | AW9: 20145785 | AX9: 21563522 | AY9: 22315486
A10: Austria | B10: 8968250.8 | C10: 8972250.1 | D10: 8555922.6 | E10: 9445770.3 | F10: 9222930.6 | G10: 9317377.5 | H10: 9549449.6 | I10: 9652741.7 | J10: 11126713 | K10: 13711004 | L10: 15061979 | M10: 16607163 | N10: 18688406 | O10: 19080219 | P10: 22322313 | Q10: 24629130 | R10: 28310704 | S10: 30288744 | T10: 43572497 | U10: 36430981 | V10: 28657788 | W10: 30721358 | X10: 29465155 | Y10: 29409851 | Z10: 26912821 | AA10: 29576674 | AB10: 31050683 | AC10: 30699933 | AD10: 29528465 | AE10: 33855480 | AF10: 32080777 | AG10: 34438221 | AH10: 31999129 | AI10: 33170724 | AJ10: 33018687 | AK10: 37084412 | AL10: 40636138 | AM10: 44342746 | AN10: 47161380 | AO10: 48299216 | AP10: 54307165 | AQ10: 52216266 | AR10: 52503011 | AS10: 57016230 | AT10: 51882412 | AU10: 53745753 | AV10: 53564854 | AW10: 54789659 | AX10: 55123562 | AY10: 57154257
A11: Azerbaijan | B11: 198563.12 | C11: 178458.65 | D11: 189635.13 | E11: 198569.65 | F11: 216548.65 | G11: 224587.47 | H11: 236958.65 | I11: 221548.79 | J11: 218768.47 | K11: 204585.65 | L11: 186958.47 | M11: 162536.13 | N11: 178452.13 | O11: 193625.13 | P11: 186596.65 | Q11: 178548.47 | R11: 198696.65 | S11: 204875.47 | T11: 216585.35 | U11: 221548.47 | V11: 235829.03 | W11: 235813.51 | X11: 235830.4 | Y11: 235770.51 | Z11: 235750.95 | AA11: 235849.06 | AB11: 235939.71 | AC11: 235805.19 | AD11: 235688.11 | AE11: 235720.77 | AF11: 235879.53 | AG11: 172526.88 | AH11: 146696.93 | AI11: 291458.69 | AJ11: 144320.71 | AK11: 297931.92 | AL11: 282855.31 | AM11: 1024623.3 | AN11: 975272.15 | AO11: 818844.42 | AP11: 994827.67 | AQ11: 1052765 | AR11: 1057619.2 | AS11: 1024254.4 | AT11: 894790.7 | AU11: 915685.65 | AV11: 926352.14 | AW11: 935478.65 | AX11: 975849.65 | AY11: 996325.17
A12: Bahrain | B12: 16525.645 | C12: 178548.65 | D12: 189658.47 | E12: 198548.65 | F12: 201548.65 | G12: 214859.65 | H12: 221478.65 | I12: 234578.13 | J12: 214859.65 | K12: 268596.65 | L12: 284859.65 | M12: 294512.12 | N12: 304856.17 | O12: 316548.65 | P12: 326548.13 | Q12: 358485.65 | R12: 414847.65 | S12: 424865.65 | T12: 448965.49 | U12: 454748.47 | V12: 468548.65 | W12: 471521.46 | X12: 481526.65 | Y12: 491523.31 | Z12: 512487.65 | AA12: 498568.65 | AB12: 478596.65 | AC12: 448596.65 | AD12: 415848.46 | AE12: 421568.47 | AF12: 412356.65 | AG12: 398568.65 | AH12: 384584.47 | AI12: 374859.46 | AJ12: 354125.46 | AK12: 341526.13 | AL12: 331478.47 | AM12: 310215.47 | AN12: 294856.65 | AO12: 221548.65 | AP12: 253658.46 | AQ12: 241502.13 | AR12: 221898.46 | AS12: 210326.46 | AT12: 198458.46 | AU12: 187568.47 | AV12: 185265.65 | AW12: 174165.47 | AX12: 165235.17 | AY12: 154878.46
A13: Bangladesh | B13: 5948687.5 | C13: 6798542.6 | D13: 6966865.1 | E13: 7076455.9 | F13: 7085779.4 | G13: 7177466.1 | H13: 7187991.4 | I13: 7198139.1 | J13: 7148614.6 | K13: 7104733.5 | L13: 7095979.6 | M13: 6990128 | N13: 6965255.4 | O13: 7106436.8 | P13: 6839639.2 | Q13: 6801171.8 | R13: 6923020.7 | S13: 6106985.4 | T13: 6493490.2 | U13: 6521927.2 | V13: 6558934.5 | W13: 6408505.6 | X13: 6363766.7 | Y13: 6273840.4 | Z13: 6268159.7 | AA13: 6162567.8 | AB13: 5811852.1 | AC13: 5883052.4 | AD13: 5849386.5 | AE13: 5857447.4 | AF13: 5857305.9 | AG13: 5857107.4 | AH13: 5856928.7 | AI13: 5856159.3 | AJ13: 5855761 | AK13: 5855108 | AL13: 5853673.5 | AM13: 5852674.9 | AN13: 5851318.9 | AO13: 5850759.6 | AP13: 5851174.5 | AQ13: 5853162 | AR13: 5855558.8 | AS13: 5859289.1 | AT13: 5863298.7 | AU13: 5548965.5 | AV13: 5312487.5 | AW13: 5132685.5 | AX13: 5031623.1 | AY13: 4985687.5
... A161: Zimbabwe | B161: 54896532 | C161: 55716396 | D161: 54876874 | E161: 53994963 | F161: 53156987 | G161: 52390967 | H161: 51650032 | I161: 51016584 | J161: 50464712 | K161: 49953066 | L161: 49449479 | M161: 48938876 | N161: 48476617 | O161: 48040915 | P161: 47610797 | Q161: 47188715 | R161: 46723059 | S161: 46267861 | T161: 45860216 | U161: 45535881 | V161: 45153009 | W161: 44986867 | X161: 44902033 | Y161: 44882404 | Z161: 44996494 | AA161: 45032283 | AB161: 45055049 | AC161: 45200417 | AD161: 45703134 | AE161: 46227928 | AF161: 46874004 | AG161: 47408326 | AH161: 47998208 | AI161: 48605568 | AJ161: 49180901 | AK161: 49684429 | AL161: 50139882 | AM161: 50481603 | AN161: 50879503 | AO161: 51294154 | AP161: 51694638 | AQ161: 52095792 | AR161: 52491066 | AS161: 52883901 | AT161: 51486958 | AU161: 50415632 | AV161: 49856858 | AW161: 49748563 | AX161: 48568596 | AY161: 47854863

Sheet co2
A1: Country Name | B1: Indicator Name | C1: 1970 | D1: 1971 | E1: 1972 | F1: 1973 | G1: 1974 | H1: 1975 | I1: 1976 | J1: 1977 | K1: 1978 | L1: 1979 | M1: 1980 | N1: 1981 | O1: 1982 | P1: 1983 | Q1: 1984 | R1: 1985 | S1: 1986 | T1: 1987 | U1: 1988 | V1: 1989 | W1: 1990 | X1: 1991 | Y1: 1992 | Z1: 1993 | AA1: 1994 | AB1: 1995 | AC1: 1996 | AD1: 1997 | AE1: 1998 | AF1: 1999 | AG1: 2000 | AH1: 2001 | AI1: 2002 | AJ1: 2003 | AK1: 2004 | AL1: 2005 | AM1: 2006 | AN1: 2007 | AO1: 2008 | AP1: 2009 | AQ1: 2010 | AR1: 2011 | AS1: 2012 | AT1: 2013 | AU1: 2014 | AV1: 2015 | AW1: 2016 | AX1: 2017 | AY1: 2018 | AZ1: 2019
A2: Afghanistan | B2: CO2 emissions (kt) | C2: 1672.152 | D2: 1895.839 | E2: 1532.806 | F2: 1639.149 | G2: 1917.841 | H2: 2126.86 | I2: 1987.514 | J2: 2390.884 | K2: 2159.863 | L2: 2240.537 | M2: 1760.16 | N2: 1983.847 | O2: 2101.191 | P2: 2522.896 | Q2: 2830.924 | R2: 3509.319 | S2: 3142.619 | T2: 3124.284 | U2: 2867.594 | V2: 2775.919 | W2: 2614.571 | X2: 2438.555 | Y2: 1393.46 | Z2: 1345.789 | AA2: 1294.451 | AB2: 1243.113 | AC2: 1177.107 | AD2: 1096.433 | AE2: 1041.428 | AF2: 821.408 | AG2: 773.737 | AH2: 817.741 | AI2: 1070.764 | AJ2: 1213.777 | AK2: 916.75 | AL2: 1327.454 | AM2: 1650.15 | AN2: 2273.54 | AO2: 4206.049 | AP2: 6769.282 | AQ2: 8463.436 | AR2: 12240.446 | AS2: 10755.311 | AT2: 9050.156 | AU2: 8467.103 | AV2: 9035.488 | AW2: 8672.455 | AX2: 8754.883 | AY2: 8973.443 | AZ2: 8993.443
A3: Albania | B3: CO2 emissions (kt) | C3: 3744.007 | D3: 4352.729 | E3: 5643.513 | F3: 5291.481 | G3: 4345.395 | H3: 4594.751 | I3: 4950.45 | J3: 5720.52 | K3: 6494.257 | L3: 7587.023 | M3: 5170.47 | N3: 7341.334 | O3: 7308.331 | P3: 7631.027 | Q3: 7825.378 | R3: 7880.383 | S3: 8056.399 | T3: 7444.01 | U3: 7326.666 | V3: 8984.15 | W3: 5515.168 | X3: 4286.723 | Y3: 2515.562 | Z3: 2335.879 | AA3: 1925.175 | AB3: 2086.523 | AC3: 2016.85 | AD3: 1543.807 | AE3: 1752.826 | AF3: 2984.938 | AG3: 3021.608 | AH3: 3223.293 | AI3: 3751.341 | AJ3: 4294.057 | AK3: 4165.712 | AL3: 4253.72 | AM3: 3898.021 | AN3: 3927.357 | AO3: 4374.731 | AP3: 4378.398 | AQ3: 4598.418 | AR3: 5240.143 | AS3: 4924.781 | AT3: 4913.78 | AU3: 5489.499 | AV3: 4616.753 | AW3: 4536.079 | AX3: 4687.332 | AY3: 4873.442 | AZ3: 4983.889
A4: Algeria | B4: CO2 emissions (kt) | C4: 15075.037 | D4: 18668.697 | E4: 28349.577 | F4: 38312.816 | G4: 31906.567 | H4: 32031.245 | I4: 39170.894 | J4: 41891.808 | K4: 62529.684 | L4: 45621.147 | M4: 66519.38 | N4: 46438.888 | O4: 39269.903 | P4: 52625.117 | Q4: 71103.13 | R4: 72786.283 | S4: 76277.267 | T4: 84120.98 | U4: 83948.631 | V4: 80046.943 | W4: 76970.33 | X4: 79049.519 | Y4: 80138.618 | Z4: 82210.473 | AA4: 86416.522 | AB4: 95294.329 | AC4: 97098.493 | AD4: 87340.606 | AE4: 106999.39 | AF4: 92045.367 | AG4: 87861.32 | AH4: 84219.989 | AI4: 89907.506 | AJ4: 91575.991 | AK4: 88510.379 | AL4: 107278.09 | AM4: 101069.85 | AN4: 109404.95 | AO4: 110208.02 | AP4: 121399.7 | AQ4: 119177.5 | AR4: 121187.02 | AS4: 129987.82 | AT4: 134465.22 | AU4: 145411.22 | AV4: 153133.92 | AW4: 150005.97 | AX4: 153434.88 | AY4: 159843.77 | AZ4: 169034.89
A5: Angola | B5: CO2 emissions (kt) | C5: 3582.659 | D5: 3410.31 | E5: 4506.743 | F5: 4880.777 | G5: 4873.443 | H5: 4415.068 | I5: 3285.632 | J5: 3534.988 | K5: 5412.492 | L5: 5504.167 | M5: 5346.486 | N5: 5280.48 | O5: 4649.756 | P5: 5115.465 | Q5: 5009.122 | R5: 4701.094 | S5: 4660.757 | T5: 5815.862 | U5: 5130.133 | V5: 5009.122 | W5: 5115.465 | X5: 5089.796 | Y5: 5196.139 | Z5: 5775.525 | AA5: 3890.687 | AB5: 10975.331 | AC5: 10458.284 | AD5: 7381.671 | AE5: 7308.331 | AF5: 9156.499 | AG5: 9541.534 | AH5: 9732.218 | AI5: 12665.818 | AJ5: 9064.824 | AK5: 18793.375 | AL5: 19156.408 | AM5: 22266.024 | AN5: 25151.953 | AO5: 25709.337 | AP5: 27792.193 | AQ5: 29057.308 | AR5: 30586.447 | AS5: 34176.44 | AT5: 33692.396 | AU5: 44851.077 | AV5: 34583.477 | AW5: 34693.487 | AX5: 35467.889 | AY5: 37654.822 | AZ5: 38943.221
A6: Argentina | B6: CO2 emissions (kt) | C6: 82734.854 | D6: 88939.418 | E6: 90156.862 | F6: 94065.884 | G6: 95569.354 | H6: 94931.296 | I6: 99786.404 | J6: 100791.16 | K6: 102639.33 | L6: 110703.06 | M6: 108737.55 | N6: 102041.61 | O6: 103424.07 | P6: 105213.56 | Q6: 106522.68 | R6: 100596.81 | S6: 104212.47 | T6: 114942.12 | U6: 121473.04 | V6: 117090.98 | W6: 112147.86 | X6: 117098.31 | Y6: 121352.03 | Z6: 117927.05 | AA6: 122408.13 | AB6: 127963.63 | AC6: 135000.61 | AD6: 138003.88 | AE6: 139815.38 | AF6: 146984.36 | AG6: 142136.59 | AH6: 133720.82 | AI6: 124714.67 | AJ6: 135062.94 | AK6: 157589.33 | AL6: 162110.74 | AM6: 175436.61 | AN6: 175176.26 | AO6: 189107.19 | AP6: 179961.69 | AQ6: 187904.41 | AR6: 191622.75 | AS6: 193027.21 | AT6: 193701.94 | AU6: 195777.46 | AV6: 201167.95 | AW6: 201347.64 | AX6: 213456.88 | AY6: 223212.82 | AZ6: 212324.88
A7: Armenia | B7: CO2 emissions (kt) | C7: 1754.251 | D7: 1875.415 | E7: 1985.457 | F7: 2156.321 | G7: 1985.452 | H7: 1854.142 | I7: 1985.625 | J7: 2054.748 | K7: 2156.325 | L7: 2548.415 | M7: 2895.457 | N7: 3264.214 | O7: 2956.254 | P7: 3065.859 | Q7: 3124.251 | R7: 3324.152 | S7: 3628.152 | T7: 3458.12 | U7: 3965.458 | V7: 4025.748 | W7: 4132.763 | X7: 4763.772 | Y7: 5826.863 | Z7: 2555.899 | AA7: 2706.246 | AB7: 3410.31 | AC7: 2563.233 | AD7: 3234.294 | AE7: 3362.639 | AF7: 3014.274 | AG7: 3465.315 | AH7: 3542.322 | AI7: 3043.61 | AJ7: 3428.645 | AK7: 3644.998 | AL7: 4349.062 | AM7: 4378.398 | AN7: 5056.793 | AO7: 5551.838 | AP7: 4360.063 | AQ7: 4209.716 | AR7: 4917.447 | AS7: 5694.851 | AT7: 5496.833 | AU7: 5529.836 | AV7: 4803.77 | AW7: 5155.802 | AX7: 5545.882 | AY7: 5645.992 | AZ7: 5893.332
A8: Aruba | B8: CO2 emissions (kt) | C8: 166.64565 | D8: 154.21564 | E8: 145.21316 | F8: 121.12156 | G8: 131.13213 | H8: 133.12236 | I8: 134.56465 | J8: 145.15646 | K8: 154.65445 | L8: 102.32116 | M8: 104.65465 | N8: 104.65465 | O8: 111.56465 | P8: 254.64565 | Q8: 143.56465 | R8: 167.65465 | S8: 179.683 | T8: 447.374 | U8: 612.389 | V8: 649.059 | W8: 487.711 | X8: 531.715 | Y8: 539.049 | Z8: 649.059 | AA8: 660.06 | AB8: 707.731 | AC8: 726.066 | AD8: 759.069 | AE8: 806.74 | AF8: 810.407 | AG8: 2379.883 | AH8: 2409.219 | AI8: 2438.555 | AJ8: 2563.233 | AK8: 2618.238 | AL8: 2720.914 | AM8: 2717.247 | AN8: 2823.59 | AO8: 2658.575 | AP8: 2629.239 | AQ8: 2508.228 | AR8: 2500.894 | AS8: 1349.456 | AT8: 861.745 | AU8: 872.746 | AV8: 898.415 | AW8: 883.747 | AX8: 893.221 | AY8: 912.324 | AZ8: 922.323
A9: Australia | B9: CO2 emissions (kt) | C9: 147618.75 | D9: 152774.55 | E9: 157486.65 | F9: 170992.21 | G9: 172356.33 | H9: 175883.99 | I9: 174244.84 | J9: 187787.07 | K9: 202015.03 | L9: 205069.64 | M9: 220746.07 | N9: 230360.94 | O9: 234119.61 | P9: 225003.45 | Q9: 236594.84 | R9: 241229.93 | S9: 239964.81 | T9: 256106.95 | U9: 261145.4 | V9: 277771.58 | W9: 263704.97 | X9: 261471.77 | Y9: 267984.36 | Z9: 277397.55 | AA9: 278119.95 | AB9: 281860.29 | AC9: 302164.47 | AD9: 305794.8 | AE9: 316883.8 | AF9: 325343.57 | AG9: 329443.28 | AH9: 324844.86 | AI9: 341353.7 | AJ9: 336271.23 | AK9: 342699.48 | AL9: 350172.83 | AM9: 365346.88 | AN9: 372090.49 | AO9: 385904.08 | AP9: 394792.89 | AQ9: 390861.86 | AR9: 391818.95 | AS9: 388126.28 | AT9: 372317.84 | AU9: 361316.84 | AV9: 365332.21 | AW9: 375907.84 | AX9: 387843.22 | AY9: 398454.77 | AZ9: 409434.88
A10: Austria | B10: CO2 emissions (kt) | C10: 50692.608 | D10: 52155.741 | E10: 56193.108 | F10: 60164.469 | G10: 57469.224 | H10: 54392.611 | I10: 58415.31 | J10: 56218.777 | K10: 57483.892 | L10: 61594.599 | M10: 52306.088 | N10: 56130.769 | O10: 53868.23 | P10: 51983.392 | Q10: 54550.292 | R10: 54700.639 | S10: 54080.916 | T10: 57744.249 | U10: 53340.182 | V10: 54117.586 | W10: 57791.92 | X10: 61719.277 | Y10: 56772.494 | Z10: 57219.868 | AA10: 57172.197 | AB10: 59918.78 | AC10: 63332.757 | AD10: 62797.375 | AE10: 63805.8 | AF10: 62016.304 | AG10: 62265.66 | AH10: 65877.655 | AI10: 67010.758 | AJ10: 71854.865 | AK10: 72140.891 | AL10: 73816.71 | AM10: 71818.195 | AN10: 69419.977 | AO10: 68811.255 | AP10: 62793.708 | AQ10: 67564.475 | AR10: 65063.581 | AS10: 62324.332 | AT10: 62529.684 | AU10: 58903.021 | AV10: 61264.569 | AW10: 61447.919 | AX10: 62343.772 | AY10: 63423.211 | AZ10: 69893.229
A11: Azerbaijan | B11: CO2 emissions (kt) | C11: 18965.521 | D11: 19856.632 | E11: 22415.748 | F11: 25364.415 | G11: 26958.963 | H11: 29658.785 | I11: 30529.854 | J11: 31254.478 | K11: 34256.385 | L11: 37458.254 | M11: 39564.415 | N11: 40523.652 | O11: 41547.489 | P11: 42516.547 | Q11: 44859.561 | R11: 46851.147 | S11: 49562.125 | T11: 50896.529 | U11: 51245.478 | V11: 52165.215 | W11: 54875.985 | X11: 55421.521 | Y11: 56240.779 | Z11: 48452.071 | AA11: 41976.149 | AB11: 33333.03 | AC11: 31257.508 | AD11: 29809.043 | AE11: 31675.546 | AF11: 28576.931 | AG11: 29508.349 | AH11: 28771.282 | AI11: 29614.692 | AJ11: 30615.783 | AK11: 32089.917 | AL11: 34337.788 | AM11: 39167.227 | AN11: 30509.44 | AO11: 35503.894 | AP11: 31902.9 | AQ11: 30678.122 | AR11: 33248.689 | AS11: 35397.551 | AT11: 35496.56 | AU11: 37385.065 | AV11: 37597.751 | AW11: 37619.753 | AX11: 38743.882 | AY11: 39843.221 | AZ11: 40932.432
A12: Bahrain | B12: CO2 emissions (kt) | C12: 2592.569 | D12: 3039.943 | E12: 3681.668 | F12: 5522.502 | G12: 5405.158 | H12: 5753.523 | I12: 6574.931 | J12: 7469.679 | K12: 7766.706 | L12: 8133.406 | M12: 7887.717 | N12: 8525.775 | O12: 9838.561 | P12: 8228.748 | Q12: 9207.837 | R12: 10194.26 | S12: 11012.001 | T12: 11430.039 | U12: 12163.439 | V12: 11738.067 | W12: 12427.463 | X12: 11877.413 | Y12: 10901.991 | Z12: 14642.331 | AA12: 14789.011 | AB12: 14818.347 | AC12: 15621.42 | AD12: 17319.241 | AE12: 18404.673 | AF12: 18019.638 | AG12: 18819.044 | AH12: 14099.615 | AI12: 15889.111 | AJ12: 16802.194 | AK12: 17953.632 | AL12: 19878.807 | AM12: 19493.772 | AN12: 26846.107 | AO12: 29768.706 | AP12: 28217.565 | AQ12: 29266.327 | AR12: 28848.289 | AS12: 27553.838 | AT12: 31407.855 | AU12: 31367.518 | AV12: 32892.99 | AW12: 31693.881 | AX12: 32432.443 | AY12: 33892.332 | AZ12: 34892.322
A13: Bangladesh | B13: CO2 emissions (kt) | C13: 24337.879 | D13: 23076.431 | E13: 3509.319 | F13: 4554.414 | G13: 4660.757 | H13: 4869.776 | I13: 5570.173 | J13: 5812.195 | K13: 6017.547 | L13: 6648.271 | M13: 7638.361 | N13: 7931.721 | O13: 8599.115 | P13: 8236.082 | Q13: 9123.496 | R13: 10234.597 | S13: 11463.042 | T13: 11862.745 | U13: 13545.898 | V13: 13454.223 | W13: 14161.954 | X13: 14811.013 | Y13: 15452.738 | Z13: 16138.467 | AA13: 17619.935 | AB13: 21129.254 | AC13: 21679.304 | AD13: 23421.129 | AE13: 23567.809 | AF13: 25705.67 | AG13: 27627.178 | AH13: 32621.632 | AI13: 33615.389 | AJ13: 35144.528 | AK13: 37682.092 | AL13: 39500.924 | AM13: 43567.627 | AN13: 44539.382 | AO13: 49625.511 | AP13: 54473.285 | AQ13: 60223.141 | AR13: 63233.748 | AS13: 67670.818 | AT13: 69456.647 | AU13: 73758.038 | AV13: 81073.703 | AW13: 84245.658 | AX13: 89873.433 | AY13: 92345.444 | AZ13: 109232.32
... A161: Zimbabwe | B161: CO2 emissions (kt) | C161: 8162.742 | D161: 8742.128 | E161: 8225.081 | F161: 9281.177 | G161: 9057.49 | H161: 8320.423 | I161: 10868.988 | J161: 9299.512 | K161: 9295.845 | L161: 9449.859 | M161: 9636.876 | N161: 9435.191 | O161: 8811.801 | P161: 10461.951 | Q161: 9922.902 | R161: 10263.933 | S161: 13127.86 | T161: 15240.052 | U161: 16101.797 | V161: 16186.138 | W161: 15643.422 | X161: 15955.117 | Y161: 17011.213 | Z161: 16362.154 | AA161: 17795.951 | AB161: 15130.042 | AC161: 14994.363 | AD161: 14407.643 | AE161: 14253.629 | AF161: 15834.106 | AG161: 13923.599 | AH161: 12596.145 | AI161: 11965.421 | AJ161: 10656.302 | AK161: 9486.529 | AL161: 10769.979 | AM161: 10447.283 | AN161: 9886.232 | AO161: 7770.373 | AP161: 5603.176 | AQ161: 7803.376 | AR161: 9622.208 | AS161: 7873.049 | AT161: 11771.07 | AU161: 12115.768 | AV161: 12317.453 | AW161: 10982.665 | AX161: 11457.471 | AY161: 12452.121 | AZ161: 13562.526

Sheet energy average
A1: Country Name | B1: Indicator Name | C1: 1970 | D1: 1971 | E1: 1972 | F1: 1973 | G1: 1974 | H1: 1975 | I1: 1976 | J1: 1977 | K1: 1978 | L1: 1979 | M1: 1980 | N1: 1981 | O1: 1982 | P1: 1983 | Q1: 1984 | R1: 1985 | S1: 1986 | T1: 1987 | U1: 1988 | V1: 1989 | W1: 1990 | X1: 1991 | Y1: 1992 | Z1: 1993 | AA1: 1994 | AB1: 1995 | AC1: 1996 | AD1: 1997 | AE1: 1998 | AF1: 1999 | AG1: 2000 | AH1: 2001 | AI1: 2002 | AJ1: 2003 | AK1: 2004 | AL1: 2005 | AM1: 2006 | AN1: 2007 | AO1: 2008 | AP1: 2009 | AQ1: 2010 | AR1: 2011 | AS1: 2012 | AT1: 2013 | AU1: 2014 | AV1: 2015 | AW1: 2016 | AX1: 2017 | AY1: 2018 | AZ1: 2019
A2: Afghanistan | B2: Energy price | C2: 0.058222 | D2: 0.059888 | E2: 0.062088 | F2: 0.064924 | G2: 0.067974 | H2: 0.070368 | I2: 0.072502 | J2: 0.075224 | K2: 0.073984 | L2: 0.07543 | M2: 0.077928 | N2: 0.079874 | O2: 0.083554 | P2: 0.082674 | Q2: 0.085036 | R2: 0.086464 | S2: 0.088402 | T2: 0.089102 | U2: 0.091284 | V2: 0.093912 | W2: 0.094922 | X2: 0.097996 | Y2: 0.100254 | Z2: 0.102428 | AA2: 0.104704 | AB2: 0.105028 | AC2: 0.105504 | AD2: 0.107478 | AE2: 0.107764 | AF2: 0.109386 | AG2: 0.114734 | AH2: 0.119518 | AI2: 0.124802 | AJ2: 0.129508 | AK2: 0.133694 | AL2: 0.13884 | AM2: 0.145516 | AN2: 0.151022 | AO2: 0.16356 | AP2: 0.16974 | AQ2: 0.16731 | AR2: 0.182878 | AS2: 0.181466 | AT2: 0.186722 | AU2: 0.186894 | AV2: 0.16506 | AW2: 0.164788 | AX2: 0.168664 | AY2: 0.175104 | AZ2: 0.18584
A3: Albania | B3: Energy price | C3: 0.058222 | D3: 0.059888 | E3: 0.062088 | F3: 0.064924 | G3: 0.067974 | H3: 0.070368 | I3: 0.072502 | J3: 0.075224 | K3: 0.073984 | L3: 0.07543 | M3: 0.077928 | N3: 0.079874 | O3: 0.083554 | P3: 0.082674 | Q3: 0.085036 | R3: 0.086464 | S3: 0.088402 | T3: 0.089102 | U3: 0.091284 | V3: 0.093912 | W3: 0.094922 | X3: 0.097996 | Y3: 0.100254 | Z3: 0.102428 | AA3: 0.104704 | AB3: 0.105028 | AC3: 0.105504 | AD3: 0.107478 | AE3: 0.107764 | AF3: 0.109386 | AG3: 0.114734 | AH3: 0.119518 | AI3: 0.124802 | AJ3: 0.129508 | AK3: 0.133694 | AL3: 0.13884 | AM3: 0.145516 | AN3: 0.151022 | AO3: 0.16356 | AP3: 0.16974 | AQ3: 0.16731 | AR3: 0.182878 | AS3: 0.181466 | AT3: 0.186722 | AU3: 0.186894 | AV3: 0.16506 | AW3: 0.164788 | AX3: 0.168664 | AY3: 0.175104 | AZ3: 0.18584
A4: Algeria | B4: Energy price | C4: 0.058222 | D4: 0.059888 | E4: 0.062088 | F4: 0.064924 | G4: 0.067974 | H4: 0.070368 | I4: 0.072502 | J4: 0.075224 | K4: 0.073984 | L4: 0.07543 | M4: 0.077928 | N4: 0.079874 | O4: 0.083554 | P4: 0.082674 | Q4: 0.085036 | R4: 0.086464 | S4: 0.088402 | T4: 0.089102 | U4: 0.091284 | V4: 0.093912 | W4: 0.094922 | X4: 0.097996 | Y4: 0.100254 | Z4: 0.102428 | AA4: 0.104704 | AB4: 0.105028 | AC4: 0.105504 | AD4: 0.107478 | AE4: 0.107764 | AF4: 0.109386 | AG4: 0.114734 | AH4: 0.119518 | AI4: 0.124802 | AJ4: 0.129508 | AK4: 0.133694 | AL4: 0.13884 | AM4: 0.145516 | AN4: 0.151022 | AO4: 0.16356 | AP4: 0.16974 | AQ4: 0.16731 | AR4: 0.182878 | AS4: 0.181466 | AT4: 0.186722 | AU4: 0.186894 | AV4: 0.16506 | AW4: 0.164788 | AX4: 0.168664 | AY4: 0.175104 | AZ4: 0.18584
A5: Angola | B5: Energy price | C5: 0.058222 | D5: 0.059888 | E5: 0.062088 | F5: 0.064924 | G5: 0.067974 | H5: 0.070368 | I5: 0.072502 | J5: 0.075224 | K5: 0.073984 | L5: 0.07543 | M5: 0.077928 | N5: 0.079874 | O5: 0.083554 | P5: 0.082674 | Q5: 0.085036 | R5: 0.086464 | S5: 0.088402 | T5: 0.089102 | U5: 0.091284 | V5: 0.093912 | W5: 0.094922 | X5: 0.097996 | Y5: 0.100254 | Z5: 0.102428 | AA5: 0.104704 | AB5: 0.105028 | AC5: 0.105504 | AD5: 0.107478 | AE5: 0.107764 | AF5: 0.109386 | AG5: 0.114734 | AH5: 0.119518 | AI5: 0.124802 | AJ5: 0.129508 | AK5: 0.133694 | AL5: 0.13884 | AM5: 0.145516 | AN5: 0.151022 | AO5: 0.16356 | AP5: 0.16974 | AQ5: 0.16731 | AR5: 0.182878 | AS5: 0.181466 | AT5: 0.186722 | AU5: 0.186894 | AV5: 0.16506 | AW5: 0.164788 | AX5: 0.168664 | AY5: 0.175104 | AZ5: 0.18584
A6: Argentina | B6: Energy price | C6: 0.058222 | D6: 0.059888 | E6: 0.062088 | F6: 0.064924 | G6: 0.067974 | H6: 0.070368 | I6: 0.072502 | J6: 0.075224 | K6: 0.073984 | L6: 0.07543 | M6: 0.077928 | N6: 0.079874 | O6: 0.083554 | P6: 0.082674 | Q6: 0.085036 | R6: 0.086464 | S6: 0.088402 | T6: 0.089102 | U6: 0.091284 | V6: 0.093912 | W6: 0.094922 | X6: 0.097996 | Y6: 0.100254 | Z6: 0.102428 | AA6: 0.104704 | AB6: 0.105028 | AC6: 0.105504 | AD6: 0.107478 | AE6: 0.107764 | AF6: 0.109386 | AG6: 0.114734 | AH6: 0.119518 | AI6: 0.124802 | AJ6: 0.129508 | AK6: 0.133694 | AL6: 0.13884 | AM6: 0.145516 | AN6: 0.151022 | AO6: 0.16356 | AP6: 0.16974 | AQ6: 0.16731 | AR6: 0.182878 | AS6: 0.181466 | AT6: 0.186722 | AU6: 0.186894 | AV6: 0.16506 | AW6: 0.164788 | AX6: 0.168664 | AY6: 0.175104 | AZ6: 0.18584
A7: Armenia | B7: Energy price | C7: 0.058222 | D7: 0.059888 | E7: 0.062088 | F7: 0.064924 | G7: 0.067974 | H7: 0.070368 | I7: 0.072502 | J7: 0.075224 | K7: 0.073984 | L7: 0.07543 | M7: 0.077928 | N7: 0.079874 | O7: 0.083554 | P7: 0.082674 | Q7: 0.085036 | R7: 0.086464 | S7: 0.088402 | T7: 0.089102 | U7: 0.091284 | V7: 0.093912 | W7: 0.094922 | X7: 0.097996 | Y7: 0.100254 | Z7: 0.102428 | AA7: 0.104704 | AB7: 0.105028 | AC7: 0.105504 | AD7: 0.107478 | AE7: 0.107764 | AF7: 0.109386 | AG7: 0.114734 | AH7: 0.119518 | AI7: 0.124802 | AJ7: 0.129508 | AK7: 0.133694 | AL7: 0.13884 | AM7: 0.145516 | AN7: 0.151022 | AO7: 0.16356 | AP7: 0.16974 | AQ7: 0.16731 | AR7: 0.182878 | AS7: 0.181466 | AT7: 0.186722 | AU7: 0.186894 | AV7: 0.16506 | AW7: 0.164788 | AX7: 0.168664 | AY7: 0.175104 | AZ7: 0.18584
A8: Aruba | B8: Energy price | C8: 0.058222 | D8: 0.059888 | E8: 0.062088 | F8: 0.064924 | G8: 0.067974 | H8: 0.070368 | I8: 0.072502 | J8: 0.075224 | K8: 0.073984 | L8: 0.07543 | M8: 0.077928 | N8: 0.079874 | O8: 0.083554 | P8: 0.082674 | Q8: 0.085036 | R8: 0.086464 | S8: 0.088402 | T8: 0.089102 | U8: 0.091284 | V8: 0.093912 | W8: 0.094922 | X8: 0.097996 | Y8: 0.100254 | Z8: 0.102428 | AA8: 0.104704 | AB8: 0.105028 | AC8: 0.105504 | AD8: 0.107478 | AE8: 0.107764 | AF8: 0.109386 | AG8: 0.114734 | AH8: 0.119518 | AI8: 0.124802 | AJ8: 0.129508 | AK8: 0.133694 | AL8: 0.13884 | AM8: 0.145516 | AN8: 0.151022 | AO8: 0.16356 | AP8: 0.16974 | AQ8: 0.16731 | AR8: 0.182878 | AS8: 0.181466 | AT8: 0.186722 | AU8: 0.186894 | AV8: 0.16506 | AW8: 0.164788 | AX8: 0.168664 | AY8: 0.175104 | AZ8: 0.18584
A9: Azerbaijan | B9: Energy price | C9: 0.058222 | D9: 0.059888 | E9: 0.062088 | F9: 0.064924 | G9: 0.067974 | H9: 0.070368 | I9: 0.072502 | J9: 0.075224 | K9: 0.073984 | L9: 0.07543 | M9: 0.077928 | N9: 0.079874 | O9: 0.083554 | P9: 0.082674 | Q9: 0.085036 | R9: 0.086464 | S9: 0.088402 | T9: 0.089102 | U9: 0.091284 | V9: 0.093912 | W9: 0.094922 | X9: 0.097996 | Y9: 0.100254 | Z9: 0.102428 | AA9: 0.104704 | AB9: 0.105028 | AC9: 0.105504 | AD9: 0.107478 | AE9: 0.107764 | AF9: 0.109386 | AG9: 0.114734 | AH9: 0.119518 | AI9: 0.124802 | AJ9: 0.129508 | AK9: 0.133694 | AL9: 0.13884 | AM9: 0.145516 | AN9: 0.151022 | AO9: 0.16356 | AP9: 0.16974 | AQ9: 0.16731 | AR9: 0.182878 | AS9: 0.181466 | AT9: 0.186722 | AU9: 0.186894 | AV9: 0.16506 | AW9: 0.164788 | AX9: 0.168664 | AY9: 0.175104 | AZ9: 0.18584
A10: Bahrain | B10: Energy price | C10: 0.058222 | D10: 0.059888 | E10: 0.062088 | F10: 0.064924 | G10: 0.067974 | H10: 0.070368 | I10: 0.072502 | J10: 0.075224 | K10: 0.073984 | L10: 0.07543 | M10: 0.077928 | N10: 0.079874 | O10: 0.083554 | P10: 0.082674 | Q10: 0.085036 | R10: 0.086464 | S10: 0.088402 | T10: 0.089102 | U10: 0.091284 | V10: 0.093912 | W10: 0.094922 | X10: 0.097996 | Y10: 0.100254 | Z10: 0.102428 | AA10: 0.104704 | AB10: 0.105028 | AC10: 0.105504 | AD10: 0.107478 | AE10: 0.107764 | AF10: 0.109386 | AG10: 0.114734 | AH10: 0.119518 | AI10: 0.124802 | AJ10: 0.129508 | AK10: 0.133694 | AL10: 0.13884 | AM10: 0.145516 | AN10: 0.151022 | AO10: 0.16356 | AP10: 0.16974 | AQ10: 0.16731 | AR10: 0.182878 | AS10: 0.181466 | AT10: 0.186722 | AU10: 0.186894 | AV10: 0.16506 | AW10: 0.164788 | AX10: 0.168664 | AY10: 0.175104 | AZ10: 0.18584
A11: Bangladesh | B11: Energy price | C11: 0.058222 | D11: 0.059888 | E11: 0.062088 | F11: 0.064924 | G11: 0.067974 | H11: 0.070368 | I11: 0.072502 | J11: 0.075224 | K11: 0.073984 | L11: 0.07543 | M11: 0.077928 | N11: 0.079874 | O11: 0.083554 | P11: 0.082674 | Q11: 0.085036 | R11: 0.086464 | S11: 0.088402 | T11: 0.089102 | U11: 0.091284 | V11: 0.093912 | W11: 0.094922 | X11: 0.097996 | Y11: 0.100254 | Z11: 0.102428 | AA11: 0.104704 | AB11: 0.105028 | AC11: 0.105504 | AD11: 0.107478 | AE11: 0.107764 | AF11: 0.109386 | AG11: 0.114734 | AH11: 0.119518 | AI11: 0.124802 | AJ11: 0.129508 | AK11: 0.133694 | AL11: 0.13884 | AM11: 0.145516 | AN11: 0.151022 | AO11: 0.16356 | AP11: 0.16974 | AQ11: 0.16731 | AR11: 0.182878 | AS11: 0.181466 | AT11: 0.186722 | AU11: 0.186894 | AV11: 0.16506 | AW11: 0.164788 | AX11: 0.168664 | AY11: 0.175104 | AZ11: 0.18584
A12: Barbados | B12: Energy price | C12: 0.058222 | D12: 0.059888 | E12: 0.062088 | F12: 0.064924 | G12: 0.067974 | H12: 0.070368 | I12: 0.072502 | J12: 0.075224 | K12: 0.073984 | L12: 0.07543 | M12: 0.077928 | N12: 0.079874 | O12: 0.083554 | P12: 0.082674 | Q12: 0.085036 | R12: 0.086464 | S12: 0.088402 | T12: 0.089102 | U12: 0.091284 | V12: 0.093912 | W12: 0.094922 | X12: 0.097996 | Y12: 0.100254 | Z12: 0.102428 | AA12: 0.104704 | AB12: 0.105028 | AC12: 0.105504 | AD12: 0.107478 | AE12: 0.107764 | AF12: 0.109386 | AG12: 0.114734 | AH12: 0.119518 | AI12: 0.124802 | AJ12: 0.129508 | AK12: 0.133694 | AL12: 0.13884 | AM12: 0.145516 | AN12: 0.151022 | AO12: 0.16356 | AP12: 0.16974 | AQ12: 0.16731 | AR12: 0.182878 | AS12: 0.181466 | AT12: 0.186722 | AU12: 0.186894 | AV12: 0.16506 | AW12: 0.164788 | AX12: 0.168664 | AY12: 0.175104 | AZ12: 0.18584
A13: Belarus | B13: Energy price | C13: 0.058222 | D13: 0.059888 | E13: 0.062088 | F13: 0.064924 | G13: 0.067974 | H13: 0.070368 | I13: 0.072502 | J13: 0.075224 | K13: 0.073984 | L13: 0.07543 | M13: 0.077928 | N13: 0.079874 | O13: 0.083554 | P13: 0.082674 | Q13: 0.085036 | R13: 0.086464 | S13: 0.088402 | T13: 0.089102 | U13: 0.091284 | V13: 0.093912 | W13: 0.094922 | X13: 0.097996 | Y13: 0.100254 | Z13: 0.102428 | AA13: 0.104704 | AB13: 0.105028 | AC13: 0.105504 | AD13: 0.107478 | AE13: 0.107764 | AF13: 0.109386 | AG13: 0.114734 | AH13: 0.119518 | AI13: 0.124802 | AJ13: 0.129508 | AK13: 0.133694 | AL13: 0.13884 | AM13: 0.145516 | AN13: 0.151022 | AO13: 0.16356 | AP13: 0.16974 | AQ13: 0.16731 | AR13: 0.182878 | AS13: 0.181466 | AT13: 0.186722 | AU13: 0.186894 | AV13: 0.16506 | AW13: 0.164788 | AX13: 0.168664 | AY13: 0.175104 | AZ13: 0.18584
... A111: Zimbabwe | B111: Energy price | C111: 0.058222 | D111: 0.059888 | E111: 0.062088 | F111: 0.064924 | G111: 0.067974 | H111: 0.070368 | I111: 0.072502 | J111: 0.075224 | K111: 0.073984 | L111: 0.07543 | M111: 0.077928 | N111: 0.079874 | O111: 0.083554 | P111: 0.082674 | Q111: 0.085036 | R111: 0.086464 | S111: 0.088402 | T111: 0.089102 | U111: 0.091284 | V111: 0.093912 | W111: 0.094922 | X111: 0.097996 | Y111: 0.100254 | Z111: 0.102428 | AA111: 0.104704 | AB111: 0.105028 | AC111: 0.105504 | AD111: 0.107478 | AE111: 0.107764 | AF111: 0.109386 | AG111: 0.114734 | AH111: 0.119518 | AI111: 0.124802 | AJ111: 0.129508 | AK111: 0.133694 | AL111: 0.13884 | AM111: 0.145516 | AN111: 0.151022 | AO111: 0.16356 | AP111: 0.16974 | AQ111: 0.16731 | AR111: 0.182878 | AS111: 0.181466 | AT111: 0.186722 | AU111: 0.186894 | AV111: 0.16506 | AW111: 0.164788 | AX111: 0.168664 | AY111: 0.175104 | AZ111: 0.18584

Sheet energy actual
A1: Country Name | B1: Indicator Name | C1: 1970 | D1: 1971 | E1: 1972 | F1: 1973 | G1: 1974 | H1: 1975 | I1: 1976 | J1: 1977 | K1: 1978 | L1: 1979 | M1: 1980 | N1: 1981 | O1: 1982 | P1: 1983 | Q1: 1984 | R1: 1985 | S1: 1986 | T1: 1987 | U1: 1988 | V1: 1989 | W1: 1990 | X1: 1991 | Y1: 1992 | Z1: 1993 | AA1: 1994 | AB1: 1995 | AC1: 1996 | AD1: 1997 | AE1: 1998 | AF1: 1999 | AG1: 2000 | AH1: 2001 | AI1: 2002 | AJ1: 2003 | AK1: 2004 | AL1: 2005 | AM1: 2006 | AN1: 2007 | AO1: 2008 | AP1: 2009 | AQ1: 2010 | AR1: 2011 | AS1: 2012 | AT1: 2013 | AU1: 2014 | AV1: 2015 | AW1: 2016 | AX1: 2017 | AY1: 2018 | AZ1: 2019
A2: Australia | B2: Energy price | C2: 0.021 | D2: 0.024 | E2: 0.027 | F2: 0.028 | G2: 0.028 | H2: 0.031 | I2: 0.039 | J2: 0.033 | K2: 0.031 | L2: 0.031 | M2: 0.037 | N2: 0.039 | O2: 0.04 | P2: 0.041 | Q2: 0.044 | R2: 0.049 | S2: 0.052 | T2: 0.051 | U2: 0.057 | V2: 0.058 | W2: 0.064 | X2: 0.068 | Y2: 0.069 | Z2: 0.072 | AA2: 0.074 | AB2: 0.071 | AC2: 0.079 | AD2: 0.082 | AE2: 0.084 | AF2: 0.084 | AG2: 0.083 | AH2: 0.091 | AI2: 0.092 | AJ2: 0.094 | AK2: 0.098 | AL2: 0.098 | AM2: 0.098 | AN2: 0.098 | AO2: 0.098 | AP2: 0.102 | AQ2: 0.135 | AR2: 0.2102 | AS2: 0.2949 | AT2: 0.2877 | AU2: 0.2833 | AV2: 0.2123 | AW2: 0.202 | AX2: 0.2371 | AY2: 0.2485 | AZ2: 0.263
A3: Austria | B3: Energy price | C3: 0.066 | D3: 0.067 | E3: 0.069 | F3: 0.079 | G3: 0.088 | H3: 0.084 | I3: 0.089 | J3: 0.095 | K3: 0.099 | L3: 0.091 | M3: 0.097 | N3: 0.095 | O3: 0.098 | P3: 0.109 | Q3: 0.121 | R3: 0.124 | S3: 0.128 | T3: 0.134 | U3: 0.128 | V3: 0.13 | W3: 0.133 | X3: 0.137 | Y3: 0.139 | Z3: 0.143 | AA3: 0.145 | AB3: 0.154 | AC3: 0.159 | AD3: 0.162 | AE3: 0.164 | AF3: 0.138 | AG3: 0.142 | AH3: 0.144 | AI3: 0.154 | AJ3: 0.152 | AK3: 0.163 | AL3: 0.158 | AM3: 0.162 | AN3: 0.18 | AO3: 0.206 | AP3: 0.218 | AQ3: 0.2576 | AR3: 0.2727 | AS3: 0.2539 | AT3: 0.2719 | AU3: 0.2669 | AV3: 0.2215 | AW3: 0.2229 | AX3: 0.2219 | AY3: 0.2302 | AZ3: 0.245
A4: Belgium | B4: Energy price | C4: 0.08 | D4: 0.08 | E4: 0.08 | F4: 0.08 | G4: 0.08 | H4: 0.09 | I4: 0.09 | J4: 0.09 | K4: 0.09 | L4: 0.1 | M4: 0.1 | N4: 0.1 | O4: 0.1 | P4: 0.11 | Q4: 0.11 | R4: 0.12 | S4: 0.12 | T4: 0.12 | U4: 0.12 | V4: 0.13 | W4: 0.13 | X4: 0.14 | Y4: 0.14 | Z4: 0.14 | AA4: 0.14 | AB4: 0.15 | AC4: 0.15 | AD4: 0.16 | AE4: 0.159 | AF4: 0.155 | AG4: 0.161 | AH4: 0.1712 | AI4: 0.1789 | AJ4: 0.1825 | AK4: 0.1844 | AL4: 0.1925 | AM4: 0.1955 | AN4: 0.201 | AO4: 0.208 | AP4: 0.193 | AQ4: 0.201 | AR4: 0.2832 | AS4: 0.272 | AT4: 0.2803 | AU4: 0.2619 | AV4: 0.2394 | AW4: 0.2922 | AX4: 0.3198 | AY4: 0.3287 | AZ4: 0.306
A5: Brazil | B5: Energy price | C5: 0.09 | D5: 0.1 | E5: 0.11 | F5: 0.124 | G5: 0.127 | H5: 0.129 | I5: 0.13 | J5: 0.131 | K5: 0.133 | L5: 0.135 | M5: 0.134 | N5: 0.138 | O5: 0.139 | P5: 0.139 | Q5: 0.146 | R5: 0.146 | S5: 0.147 | T5: 0.147 | U5: 0.15 | V5: 0.151 | W5: 0.155 | X5: 0.154 | Y5: 0.161 | Z5: 0.162 | AA5: 0.164 | AB5: 0.169 | AC5: 0.172 | AD5: 0.174 | AE5: 0.174 | AF5: 0.176 | AG5: 0.179 | AH5: 0.189 | AI5: 0.187 | AJ5: 0.185 | AK5: 0.194 | AL5: 0.195 | AM5: 0.198 | AN5: 0.207 | AO5: 0.217 | AP5: 0.206 | AQ5: 0.206 | AR5: 0.198 | AS5: 0.187 | AT5: 0.185 | AU5: 0.174 | AV5: 0.176 | AW5: 0.168 | AX5: 0.164 | AY5: 0.155 | AZ5: 0.145
A6: Bulgaria | B6: Energy price | C6: 0.04 | D6: 0.04 | E6: 0.04 | F6: 0.04 | G6: 0.04 | H6: 0.04 | I6: 0.041 | J6: 0.044 | K6: 0.048 | L6: 0.044 | M6: 0.047 | N6: 0.052 | O6: 0.051 | P6: 0.049 | Q6: 0.058 | R6: 0.058 | S6: 0.059 | T6: 0.061 | U6: 0.057 | V6: 0.052 | W6: 0.059 | X6: 0.054 | Y6: 0.068 | Z6: 0.068 | AA6: 0.069 | AB6: 0.071 | AC6: 0.074 | AD6: 0.075 | AE6: 0.087 | AF6: 0.077 | AG6: 0.078 | AH6: 0.091 | AI6: 0.089 | AJ6: 0.095 | AK6: 0.098 | AL6: 0.107 | AM6: 0.109 | AN6: 0.118 | AO6: 0.113 | AP6: 0.114 | AQ6: 0.108 | AR6: 0.115 | AS6: 0.156 | AT6: 0.142 | AU6: 0.165 | AV6: 0.144 | AW6: 0.178 | AX6: 0.158 | AY6: 0.148 | AZ6: 0.138
A7: Canada | B7: Energy price | C7: 0.02 | D7: 0.021 | E7: 0.029 | F7: 0.034 | G7: 0.039 | H7: 0.038 | I7: 0.034 | J7: 0.039 | K7: 0.031 | L7: 0.034 | M7: 0.033 | N7: 0.039 | O7: 0.04 | P7: 0.041 | Q7: 0.044 | R7: 0.049 | S7: 0.048 | T7: 0.043 | U7: 0.044 | V7: 0.047 | W7: 0.049 | X7: 0.057 | Y7: 0.059 | Z7: 0.055 | AA7: 0.057 | AB7: 0.059 | AC7: 0.061 | AD7: 0.066 | AE7: 0.068 | AF7: 0.068 | AG7: 0.064 | AH7: 0.067 | AI7: 0.069 | AJ7: 0.07 | AK7: 0.071 | AL7: 0.076 | AM7: 0.077 | AN7: 0.079 | AO7: 0.078 | AP7: 0.081 | AQ7: 0.0933 | AR7: 0.1049 | AS7: 0.1045 | AT7: 0.1038 | AU7: 0.0987 | AV7: 0.0927 | AW7: 0.1063 | AX7: 0.109 | AY7: 0.113 | AZ7: 0.109
A8: Chile | B8: Energy price | C8: 0.024 | D8: 0.024 | E8: 0.024 | F8: 0.024 | G8: 0.027 | H8: 0.027 | I8: 0.028 | J8: 0.028 | K8: 0.029 | L8: 0.031 | M8: 0.033 | N8: 0.032 | O8: 0.033 | P8: 0.037 | Q8: 0.039 | R8: 0.041 | S8: 0.042 | T8: 0.048 | U8: 0.044 | V8: 0.049 | W8: 0.05 | X8: 0.052 | Y8: 0.051 | Z8: 0.054 | AA8: 0.059 | AB8: 0.06 | AC8: 0.061 | AD8: 0.063 | AE8: 0.055 | AF8: 0.098 | AG8: 0.163 | AH8: 0.178 | AI8: 0.185 | AJ8: 0.189 | AK8: 0.184 | AL8: 0.201 | AM8: 0.199 | AN8: 0.233 | AO8: 0.331 | AP8: 0.317 | AQ8: 0.2088 | AR8: 0.2108 | AS8: 0.1854 | AT8: 0.1723 | AU8: 0.1514 | AV8: 0.1578 | AW8: 0.1693 | AX8: 0.1993 | AY8: 0.197 | AZ8: 0.197
A9: China | B9: Energy price | C9: 0.01 | D9: 0.01 | E9: 0.017 | F9: 0.017 | G9: 0.018 | H9: 0.018 | I9: 0.019 | J9: 0.019 | K9: 0.019 | L9: 0.021 | M9: 0.021 | N9: 0.021 | O9: 0.029 | P9: 0.029 | Q9: 0.029 | R9: 0.029 | S9: 0.031 | T9: 0.031 | U9: 0.032 | V9: 0.032 | W9: 0.032 | X9: 0.032 | Y9: 0.0332 | Z9: 0.045 | AA9: 0.045 | AB9: 0.045 | AC9: 0.045 | AD9: 0.05 | AE9: 0.051 | AF9: 0.051 | AG9: 0.051 | AH9: 0.053 | AI9: 0.053 | AJ9: 0.053 | AK9: 0.063 | AL9: 0.063 | AM9: 0.063 | AN9: 0.064 | AO9: 0.064 | AP9: 0.064 | AQ9: 0.068 | AR9: 0.069 | AS9: 0.07 | AT9: 0.07 | AU9: 0.07 | AV9: 0.07 | AW9: 0.07 | AX9: 0.08 | AY9: 0.08 | AZ9: 0.084
A10: Costa Rica | B10: Energy price | C10: 0.052 | D10: 0.053 | E10: 0.051 | F10: 0.052 | G10: 0.059 | H10: 0.058 | I10: 0.054 | J10: 0.063 | K10: 0.061 | L10: 0.058 | M10: 0.052 | N10: 0.052 | O10: 0.054 | P10: 0.054 | Q10: 0.057 | R10: 0.057 | S10: 0.058 | T10: 0.058 | U10: 0.059 | V10: 0.06 | W10: 0.062 | X10: 0.063 | Y10: 0.063 | Z10: 0.063 | AA10: 0.062 | AB10: 0.061 | AC10: 0.064 | AD10: 0.065 | AE10: 0.069 | AF10: 0.078 | AG10: 0.074 | AH10: 0.071 | AI10: 0.079 | AJ10: 0.074 | AK10: 0.084 | AL10: 0.085 | AM10: 0.087 | AN10: 0.096 | AO10: 0.097 | AP10: 0.113 | AQ10: 0.114 | AR10: 0.121 | AS10: 0.127 | AT10: 0.128 | AU10: 0.134 | AV10: 0.139 | AW10: 0.141 | AX10: 0.148 | AY10: 0.149 | AZ10: 0.152
A11: Croatia | B11: Energy price | C11: 0.021 | D11: 0.024 | E11: 0.017 | F11: 0.015 | G11: 0.021 | H11: 0.025 | I11: 0.027 | J11: 0.028 | K11: 0.024 | L11: 0.021 | M11: 0.025 | N11: 0.027 | O11: 0.029 | P11: 0.029 | Q11: 0.038 | R11: 0.031 | S11: 0.034 | T11: 0.031 | U11: 0.039 | V11: 0.037 | W11: 0.038 | X11: 0.039 | Y11: 0.042 | Z11: 0.041 | AA11: 0.043 | AB11: 0.044 | AC11: 0.041 | AD11: 0.044 | AE11: 0.047 | AF11: 0.049 | AG11: 0.051 | AH11: 0.061 | AI11: 0.065 | AJ11: 0.082 | AK11: 0.087 | AL11: 0.098 | AM11: 0.115 | AN11: 0.121 | AO11: 0.132 | AP11: 0.158 | AQ11: 0.163 | AR11: 0.156 | AS11: 0.145 | AT11: 0.138 | AU11: 0.135 | AV11: 0.125 | AW11: 0.147 | AX11: 0.149 | AY11: 0.158 | AZ11: 0.165
A12: Cuba | B12: Energy price | C12: 0.003 | D12: 0.003 | E12: 0.006 | F12: 0.005 | G12: 0.005 | H12: 0.004 | I12: 0.008 | J12: 0.009 | K12: 0.009 | L12: 0.01 | M12: 0.011 | N12: 0.012 | O12: 0.014 | P12: 0.015 | Q12: 0.017 | R12: 0.015 | S12: 0.019 | T12: 0.019 | U12: 0.023 | V12: 0.021 | W12: 0.024 | X12: 0.027 | Y12: 0.029 | Z12: 0.032 | AA12: 0.034 | AB12: 0.031 | AC12: 0.038 | AD12: 0.039 | AE12: 0.042 | AF12: 0.042 | AG12: 0.041 | AH12: 0.049 | AI12: 0.057 | AJ12: 0.059 | AK12: 0.052 | AL12: 0.064 | AM12: 0.062 | AN12: 0.054 | AO12: 0.079 | AP12: 0.069 | AQ12: 0.074 | AR12: 0.075 | AS12: 0.075 | AT12: 0.071 | AU12: 0.068 | AV12: 0.064 | AW12: 0.051 | AX12: 0.052 | AY12: 0.051 | AZ12: 0.058
A13: Cyprus | B13: Energy price | C13: 0.138 | D13: 0.138 | E13: 0.139 | F13: 0.139 | G13: 0.141 | H13: 0.142 | I13: 0.152 | J13: 0.153 | K13: 0.142 | L13: 0.156 | M13: 0.177 | N13: 0.179 | O13: 0.181 | P13: 0.183 | Q13: 0.181 | R13: 0.191 | S13: 0.193 | T13: 0.197 | U13: 0.231 | V13: 0.243 | W13: 0.221 | X13: 0.288 | Y13: 0.253 | Z13: 0.263 | AA13: 0.283 | AB13: 0.271 | AC13: 0.274 | AD13: 0.289 | AE13: 0.245 | AF13: 0.265 | AG13: 0.224 | AH13: 0.234 | AI13: 0.237 | AJ13: 0.238 | AK13: 0.254 | AL13: 0.247 | AM13: 0.245 | AN13: 0.211 | AO13: 0.281 | AP13: 0.221 | AQ13: 0.255 | AR13: 0.267 | AS13: 0.264 | AT13: 0.267 | AU13: 0.277 | AV13: 0.245 | AW13: 0.248 | AX13: 0.258 | AY13: 0.276 | AZ13: 0.286
... A51: United States | B51: Energy price | C51: 0.019 | D51: 0.024 | E51: 0.021 | F51: 0.029 | G51: 0.031 | H51: 0.035 | I51: 0.034 | J51: 0.038 | K51: 0.045 | L51: 0.041 | M51: 0.047 | N51: 0.049 | O51: 0.053 | P51: 0.052 | Q51: 0.054 | R51: 0.059 | S51: 0.067 | T51: 0.062 | U51: 0.061 | V51: 0.064 | W51: 0.072 | X51: 0.071 | Y51: 0.079 | Z51: 0.085 | AA51: 0.086 | AB51: 0.081 | AC51: 0.085 | AD51: 0.084 | AE51: 0.083 | AF51: 0.082 | AG51: 0.082 | AH51: 0.085 | AI51: 0.085 | AJ51: 0.087 | AK51: 0.09 | AL51: 0.094 | AM51: 0.104 | AN51: 0.107 | AO51: 0.113 | AP51: 0.115 | AQ51: 0.1158 | AR51: 0.1172 | AS51: 0.1188 | AT51: 0.1212 | AU51: 0.1252 | AV51: 0.1265 | AW51: 0.1255 | AX51: 0.1289 | AY51: 0.1289 | AZ51: 0.149
A52: Average price | B52: 0 | C52: 0.058222 | D52: 0.059888 | E52: 0.062088 | F52: 0.064924 | G52: 0.067974 | H52: 0.070368 | I52: 0.072502 | J52: 0.075224 | K52: 0.073984 | L52: 0.07543 | M52: 0.077928 | N52: 0.079874 | O52: 0.083554 | P52: 0.082674 | Q52: 0.085036 | R52: 0.086464 | S52: 0.088402 | T52: 0.089102 | U52: 0.091284 | V52: 0.093912 | W52: 0.094922 | X52: 0.097996 | Y52: 0.100254 | Z52: 0.102428 | AA52: 0.104704 | AB52: 0.105028 | AC52: 0.105504 | AD52: 0.107478 | AE52: 0.107764 | AF52: 0.109386 | AG52: 0.114734 | AH52: 0.119518 | AI52: 0.124802 | AJ52: 0.129508 | AK52: 0.133694 | AL52: 0.13884 | AM52: 0.145516 | AN52: 0.151022 | AO52: 0.16356 | AP52: 0.16974 | AQ52: 0.16731 | AR52: 0.182878 | AS52: 0.181466 | AT52: 0.186722 | AU52: 0.186894 | AV52: 0.16506 | AW52: 0.164788 | AX52: 0.168664 | AY52: 0.175104 | AZ52: 0.18584

Sheet energy
A1: Country Name | B1: Indicator Name | C1: 1970 | D1: 1971 | E1: 1972 | F1: 1973 | G1: 1974 | H1: 1975 | I1: 1976 | J1: 1977 | K1: 1978 | L1: 1979 | M1: 1980 | N1: 1981 | O1: 1982 | P1: 1983 | Q1: 1984 | R1: 1985 | S1: 1986 | T1: 1987 | U1: 1988 | V1: 1989 | W1: 1990 | X1: 1991 | Y1: 1992 | Z1: 1993 | AA1: 1994 | AB1: 1995 | AC1: 1996 | AD1: 1997 | AE1: 1998 | AF1: 1999 | AG1: 2000 | AH1: 2001 | AI1: 2002 | AJ1: 2003 | AK1: 2004 | AL1: 2005 | AM1: 2006 | AN1: 2007 | AO1: 2008 | AP1: 2009 | AQ1: 2010 | AR1: 2011 | AS1: 2012 | AT1: 2013 | AU1: 2014 | AV1: 2015 | AW1: 2016 | AX1: 2017 | AY1: 2018 | AZ1: 2019
A2: Afghanistan | B2: Energy price | C2: 0.058222 | D2: 0.059888 | E2: 0.062088 | F2: 0.064924 | G2: 0.067974 | H2: 0.070368 | I2: 0.072502 | J2: 0.075224 | K2: 0.073984 | L2: 0.07543 | M2: 0.077928 | N2: 0.079874 | O2: 0.083554 | P2: 0.082674 | Q2: 0.085036 | R2: 0.086464 | S2: 0.088402 | T2: 0.089102 | U2: 0.091284 | V2: 0.093912 | W2: 0.094922 | X2: 0.097996 | Y2: 0.100254 | Z2: 0.102428 | AA2: 0.104704 | AB2: 0.105028 | AC2: 0.105504 | AD2: 0.107478 | AE2: 0.107764 | AF2: 0.109386 | AG2: 0.114734 | AH2: 0.119518 | AI2: 0.124802 | AJ2: 0.129508 | AK2: 0.133694 | AL2: 0.13884 | AM2: 0.145516 | AN2: 0.151022 | AO2: 0.16356 | AP2: 0.16974 | AQ2: 0.16731 | AR2: 0.182878 | AS2: 0.181466 | AT2: 0.186722 | AU2: 0.186894 | AV2: 0.16506 | AW2: 0.164788 | AX2: 0.168664 | AY2: 0.175104 | AZ2: 0.18584
A3: Albania | B3: Energy price | C3: 0.058222 | D3: 0.059888 | E3: 0.062088 | F3: 0.064924 | G3: 0.067974 | H3: 0.070368 | I3: 0.072502 | J3: 0.075224 | K3: 0.073984 | L3: 0.07543 | M3: 0.077928 | N3: 0.079874 | O3: 0.083554 | P3: 0.082674 | Q3: 0.085036 | R3: 0.086464 | S3: 0.088402 | T3: 0.089102 | U3: 0.091284 | V3: 0.093912 | W3: 0.094922 | X3: 0.097996 | Y3: 0.100254 | Z3: 0.102428 | AA3: 0.104704 | AB3: 0.105028 | AC3: 0.105504 | AD3: 0.107478 | AE3: 0.107764 | AF3: 0.109386 | AG3: 0.114734 | AH3: 0.119518 | AI3: 0.124802 | AJ3: 0.129508 | AK3: 0.133694 | AL3: 0.13884 | AM3: 0.145516 | AN3: 0.151022 | AO3: 0.16356 | AP3: 0.16974 | AQ3: 0.16731 | AR3: 0.182878 | AS3: 0.181466 | AT3: 0.186722 | AU3: 0.186894 | AV3: 0.16506 | AW3: 0.164788 | AX3: 0.168664 | AY3: 0.175104 | AZ3: 0.18584
A4: Algeria | B4: Energy price | C4: 0.058222 | D4: 0.059888 | E4: 0.062088 | F4: 0.064924 | G4: 0.067974 | H4: 0.070368 | I4: 0.072502 | J4: 0.075224 | K4: 0.073984 | L4: 0.07543 | M4: 0.077928 | N4: 0.079874 | O4: 0.083554 | P4: 0.082674 | Q4: 0.085036 | R4: 0.086464 | S4: 0.088402 | T4: 0.089102 | U4: 0.091284 | V4: 0.093912 | W4: 0.094922 | X4: 0.097996 | Y4: 0.100254 | Z4: 0.102428 | AA4: 0.104704 | AB4: 0.105028 | AC4: 0.105504 | AD4: 0.107478 | AE4: 0.107764 | AF4: 0.109386 | AG4: 0.114734 | AH4: 0.119518 | AI4: 0.124802 | AJ4: 0.129508 | AK4: 0.133694 | AL4: 0.13884 | AM4: 0.145516 | AN4: 0.151022 | AO4: 0.16356 | AP4: 0.16974 | AQ4: 0.16731 | AR4: 0.182878 | AS4: 0.181466 | AT4: 0.186722 | AU4: 0.186894 | AV4: 0.16506 | AW4: 0.164788 | AX4: 0.168664 | AY4: 0.175104 | AZ4: 0.18584
A5: Angola | B5: Energy price | C5: 0.058222 | D5: 0.059888 | E5: 0.062088 | F5: 0.064924 | G5: 0.067974 | H5: 0.070368 | I5: 0.072502 | J5: 0.075224 | K5: 0.073984 | L5: 0.07543 | M5: 0.077928 | N5: 0.079874 | O5: 0.083554 | P5: 0.082674 | Q5: 0.085036 | R5: 0.086464 | S5: 0.088402 | T5: 0.089102 | U5: 0.091284 | V5: 0.093912 | W5: 0.094922 | X5: 0.097996 | Y5: 0.100254 | Z5: 0.102428 | AA5: 0.104704 | AB5: 0.105028 | AC5: 0.105504 | AD5: 0.107478 | AE5: 0.107764 | AF5: 0.109386 | AG5: 0.114734 | AH5: 0.119518 | AI5: 0.124802 | AJ5: 0.129508 | AK5: 0.133694 | AL5: 0.13884 | AM5: 0.145516 | AN5: 0.151022 | AO5: 0.16356 | AP5: 0.16974 | AQ5: 0.16731 | AR5: 0.182878 | AS5: 0.181466 | AT5: 0.186722 | AU5: 0.186894 | AV5: 0.16506 | AW5: 0.164788 | AX5: 0.168664 | AY5: 0.175104 | AZ5: 0.18584
A6: Argentina | B6: Energy price | C6: 0.058222 | D6: 0.059888 | E6: 0.062088 | F6: 0.064924 | G6: 0.067974 | H6: 0.070368 | I6: 0.072502 | J6: 0.075224 | K6: 0.073984 | L6: 0.07543 | M6: 0.077928 | N6: 0.079874 | O6: 0.083554 | P6: 0.082674 | Q6: 0.085036 | R6: 0.086464 | S6: 0.088402 | T6: 0.089102 | U6: 0.091284 | V6: 0.093912 | W6: 0.094922 | X6: 0.097996 | Y6: 0.100254 | Z6: 0.102428 | AA6: 0.104704 | AB6: 0.105028 | AC6: 0.105504 | AD6: 0.107478 | AE6: 0.107764 | AF6: 0.109386 | AG6: 0.114734 | AH6: 0.119518 | AI6: 0.124802 | AJ6: 0.129508 | AK6: 0.133694 | AL6: 0.13884 | AM6: 0.145516 | AN6: 0.151022 | AO6: 0.16356 | AP6: 0.16974 | AQ6: 0.16731 | AR6: 0.182878 | AS6: 0.181466 | AT6: 0.186722 | AU6: 0.186894 | AV6: 0.16506 | AW6: 0.164788 | AX6: 0.168664 | AY6: 0.175104 | AZ6: 0.18584
A7: Armenia | B7: Energy price | C7: 0.058222 | D7: 0.059888 | E7: 0.062088 | F7: 0.064924 | G7: 0.067974 | H7: 0.070368 | I7: 0.072502 | J7: 0.075224 | K7: 0.073984 | L7: 0.07543 | M7: 0.077928 | N7: 0.079874 | O7: 0.083554 | P7: 0.082674 | Q7: 0.085036 | R7: 0.086464 | S7: 0.088402 | T7: 0.089102 | U7: 0.091284 | V7: 0.093912 | W7: 0.094922 | X7: 0.097996 | Y7: 0.100254 | Z7: 0.102428 | AA7: 0.104704 | AB7: 0.105028 | AC7: 0.105504 | AD7: 0.107478 | AE7: 0.107764 | AF7: 0.109386 | AG7: 0.114734 | AH7: 0.119518 | AI7: 0.124802 | AJ7: 0.129508 | AK7: 0.133694 | AL7: 0.13884 | AM7: 0.145516 | AN7: 0.151022 | AO7: 0.16356 | AP7: 0.16974 | AQ7: 0.16731 | AR7: 0.182878 | AS7: 0.181466 | AT7: 0.186722 | AU7: 0.186894 | AV7: 0.16506 | AW7: 0.164788 | AX7: 0.168664 | AY7: 0.175104 | AZ7: 0.18584
A8: Aruba | B8: Energy price | C8: 0.058222 | D8: 0.059888 | E8: 0.062088 | F8: 0.064924 | G8: 0.067974 | H8: 0.070368 | I8: 0.072502 | J8: 0.075224 | K8: 0.073984 | L8: 0.07543 | M8: 0.077928 | N8: 0.079874 | O8: 0.083554 | P8: 0.082674 | Q8: 0.085036 | R8: 0.086464 | S8: 0.088402 | T8: 0.089102 | U8: 0.091284 | V8: 0.093912 | W8: 0.094922 | X8: 0.097996 | Y8: 0.100254 | Z8: 0.102428 | AA8: 0.104704 | AB8: 0.105028 | AC8: 0.105504 | AD8: 0.107478 | AE8: 0.107764 | AF8: 0.109386 | AG8: 0.114734 | AH8: 0.119518 | AI8: 0.124802 | AJ8: 0.129508 | AK8: 0.133694 | AL8: 0.13884 | AM8: 0.145516 | AN8: 0.151022 | AO8: 0.16356 | AP8: 0.16974 | AQ8: 0.16731 | AR8: 0.182878 | AS8: 0.181466 | AT8: 0.186722 | AU8: 0.186894 | AV8: 0.16506 | AW8: 0.164788 | AX8: 0.168664 | AY8: 0.175104 | AZ8: 0.18584
A9: Australia | B9: Energy price | C9: 0.021 | D9: 0.024 | E9: 0.027 | F9: 0.028 | G9: 0.028 | H9: 0.031 | I9: 0.039 | J9: 0.033 | K9: 0.031 | L9: 0.031 | M9: 0.037 | N9: 0.039 | O9: 0.04 | P9: 0.041 | Q9: 0.044 | R9: 0.049 | S9: 0.052 | T9: 0.051 | U9: 0.057 | V9: 0.058 | W9: 0.064 | X9: 0.068 | Y9: 0.069 | Z9: 0.072 | AA9: 0.074 | AB9: 0.071 | AC9: 0.079 | AD9: 0.082 | AE9: 0.084 | AF9: 0.084 | AG9: 0.083 | AH9: 0.091 | AI9: 0.092 | AJ9: 0.094 | AK9: 0.098 | AL9: 0.098 | AM9: 0.098 | AN9: 0.098 | AO9: 0.098 | AP9: 0.102 | AQ9: 0.135 | AR9: 0.2102 | AS9: 0.2949 | AT9: 0.2877 | AU9: 0.2833 | AV9: 0.2123 | AW9: 0.202 | AX9: 0.2371 | AY9: 0.2485 | AZ9: 0.263
A10: Austria | B10: Energy price | C10: 0.066 | D10: 0.067 | E10: 0.069 | F10: 0.079 | G10: 0.088 | H10: 0.084 | I10: 0.089 | J10: 0.095 | K10: 0.099 | L10: 0.091 | M10: 0.097 | N10: 0.095 | O10: 0.098 | P10: 0.109 | Q10: 0.121 | R10: 0.124 | S10: 0.128 | T10: 0.134 | U10: 0.128 | V10: 0.13 | W10: 0.133 | X10: 0.137 | Y10: 0.139 | Z10: 0.143 | AA10: 0.145 | AB10: 0.154 | AC10: 0.159 | AD10: 0.162 | AE10: 0.164 | AF10: 0.138 | AG10: 0.142 | AH10: 0.144 | AI10: 0.154 | AJ10: 0.152 | AK10: 0.163 | AL10: 0.158 | AM10: 0.162 | AN10: 0.18 | AO10: 0.206 | AP10: 0.218 | AQ10: 0.2576 | AR10: 0.2727 | AS10: 0.2539 | AT10: 0.2719 | AU10: 0.2669 | AV10: 0.2215 | AW10: 0.2229 | AX10: 0.2219 | AY10: 0.2302 | AZ10: 0.245
A11: Azerbaijan | B11: Energy price | C11: 0.058222 | D11: 0.059888 | E11: 0.062088 | F11: 0.064924 | G11: 0.067974 | H11: 0.070368 | I11: 0.072502 | J11: 0.075224 | K11: 0.073984 | L11: 0.07543 | M11: 0.077928 | N11: 0.079874 | O11: 0.083554 | P11: 0.082674 | Q11: 0.085036 | R11: 0.086464 | S11: 0.088402 | T11: 0.089102 | U11: 0.091284 | V11: 0.093912 | W11: 0.094922 | X11: 0.097996 | Y11: 0.100254 | Z11: 0.102428 | AA11: 0.104704 | AB11: 0.105028 | AC11: 0.105504 | AD11: 0.107478 | AE11: 0.107764 | AF11: 0.109386 | AG11: 0.114734 | AH11: 0.119518 | AI11: 0.124802 | AJ11: 0.129508 | AK11: 0.133694 | AL11: 0.13884 | AM11: 0.145516 | AN11: 0.151022 | AO11: 0.16356 | AP11: 0.16974 | AQ11: 0.16731 | AR11: 0.182878 | AS11: 0.181466 | AT11: 0.186722 | AU11: 0.186894 | AV11: 0.16506 | AW11: 0.164788 | AX11: 0.168664 | AY11: 0.175104 | AZ11: 0.18584
A12: Bahrain | B12: Energy price | C12: 0.058222 | D12: 0.059888 | E12: 0.062088 | F12: 0.064924 | G12: 0.067974 | H12: 0.070368 | I12: 0.072502 | J12: 0.075224 | K12: 0.073984 | L12: 0.07543 | M12: 0.077928 | N12: 0.079874 | O12: 0.083554 | P12: 0.082674 | Q12: 0.085036 | R12: 0.086464 | S12: 0.088402 | T12: 0.089102 | U12: 0.091284 | V12: 0.093912 | W12: 0.094922 | X12: 0.097996 | Y12: 0.100254 | Z12: 0.102428 | AA12: 0.104704 | AB12: 0.105028 | AC12: 0.105504 | AD12: 0.107478 | AE12: 0.107764 | AF12: 0.109386 | AG12: 0.114734 | AH12: 0.119518 | AI12: 0.124802 | AJ12: 0.129508 | AK12: 0.133694 | AL12: 0.13884 | AM12: 0.145516 | AN12: 0.151022 | AO12: 0.16356 | AP12: 0.16974 | AQ12: 0.16731 | AR12: 0.182878 | AS12: 0.181466 | AT12: 0.186722 | AU12: 0.186894 | AV12: 0.16506 | AW12: 0.164788 | AX12: 0.168664 | AY12: 0.175104 | AZ12: 0.18584
A13: Bangladesh | B13: Energy price | C13: 0.058222 | D13: 0.059888 | E13: 0.062088 | F13: 0.064924 | G13: 0.067974 | H13: 0.070368 | I13: 0.072502 | J13: 0.075224 | K13: 0.073984 | L13: 0.07543 | M13: 0.077928 | N13: 0.079874 | O13: 0.083554 | P13: 0.082674 | Q13: 0.085036 | R13: 0.086464 | S13: 0.088402 | T13: 0.089102 | U13: 0.091284 | V13: 0.093912 | W13: 0.094922 | X13: 0.097996 | Y13: 0.100254 | Z13: 0.102428 | AA13: 0.104704 | AB13: 0.105028 | AC13: 0.105504 | AD13: 0.107478 | AE13: 0.107764 | AF13: 0.109386 | AG13: 0.114734 | AH13: 0.119518 | AI13: 0.124802 | AJ13: 0.129508 | AK13: 0.133694 | AL13: 0.13884 | AM13: 0.145516 | AN13: 0.151022 | AO13: 0.16356 | AP13: 0.16974 | AQ13: 0.16731 | AR13: 0.182878 | AS13: 0.181466 | AT13: 0.186722 | AU13: 0.186894 | AV13: 0.16506 | AW13: 0.164788 | AX13: 0.168664 | AY13: 0.175104 | AZ13: 0.18584
... A161: Zimbabwe | B161: Energy price | C161: 0.058222 | D161: 0.059888 | E161: 0.062088 | F161: 0.064924 | G161: 0.067974 | H161: 0.070368 | I161: 0.072502 | J161: 0.075224 | K161: 0.073984 | L161: 0.07543 | M161: 0.077928 | N161: 0.079874 | O161: 0.083554 | P161: 0.082674 | Q161: 0.085036 | R161: 0.086464 | S161: 0.088402 | T161: 0.089102 | U161: 0.091284 | V161: 0.093912 | W161: 0.094922 | X161: 0.097996 | Y161: 0.100254 | Z161: 0.102428 | AA161: 0.104704 | AB161: 0.105028 | AC161: 0.105504 | AD161: 0.107478 | AE161: 0.107764 | AF161: 0.109386 | AG161: 0.114734 | AH161: 0.119518 | AI161: 0.124802 | AJ161: 0.129508 | AK161: 0.133694 | AL161: 0.13884 | AM161: 0.145516 | AN161: 0.151022 | AO161: 0.16356 | AP161: 0.16974 | AQ161: 0.16731 | AR161: 0.182878 | AS161: 0.181466 | AT161: 0.186722 | AU161: 0.186894 | AV161: 0.16506 | AW161: 0.164788 | AX161: 0.168664 | AY161: 0.175104 | AZ161: 0.18584

Sheet gni
A1: Country Name | B1: Indicator Name | C1: 1970 | D1: 1971 | E1: 1972 | F1: 1973 | G1: 1974 | H1: 1975 | I1: 1976 | J1: 1977 | K1: 1978 | L1: 1979 | M1: 1980 | N1: 1981 | O1: 1982 | P1: 1983 | Q1: 1984 | R1: 1985 | S1: 1986 | T1: 1987 | U1: 1988 | V1: 1989 | W1: 1990 | X1: 1991 | Y1: 1992 | Z1: 1993 | AA1: 1994 | AB1: 1995 | AC1: 1996 | AD1: 1997 | AE1: 1998 | AF1: 1999 | AG1: 2000 | AH1: 2001 | AI1: 2002 | AJ1: 2003 | AK1: 2004 | AL1: 2005 | AM1: 2006 | AN1: 2007 | AO1: 2008 | AP1: 2009 | AQ1: 2010 | AR1: 2011 | AS1: 2012 | AT1: 2013 | AU1: 2014 | AV1: 2015 | AW1: 2016 | AX1: 2017 | AY1: 2018 | AZ1: 2019
A2: Afghanistan | B2: GNI, Atlas method (current US$) | C2: 6425985985 | D2: 6525325415 | E2: 6589564585 | F2: 6658478596 | G2: 6741589563 | H2: 6845852685 | I2: 6958693654 | J2: 7085263598 | K2: 7145289695 | L2: 7254784587 | M2: 7356859859 | N2: 7451896895 | O2: 7845125489 | P2: 7985468549 | Q2: 8059896936 | R2: 8145784989 | S2: 8154689563 | T2: 8245189689 | U2: 8356854289 | V2: 8475896356 | W2: 8547512584 | X2: 8696359869 | Y2: 8796859868 | Z2: 8856926589 | AA2: 8956847859 | AB2: 9056898458 | AC2: 9154872563 | AD2: 9365896748 | AE2: 9458689748 | AF2: 9568562385 | AG2: 9784856895 | AH2: 9985685968 | AI2: 10036589652 | AJ2: 10145784985 | AK2: 10252541789 | AL2: 10452895689 | AM2: 10526963589 | AN2: 11474859685 | AO2: 11524528954 | AP2: 1.2652733e+10 | AQ2: 1.4872476e+10 | AR2: 1.6077121e+10 | AS2: 1.9583318e+10 | AT2: 2.1249374e+10 | AU2: 2.1141556e+10 | AV2: 2.0583397e+10 | AW2: 2.0092934e+10 | AX2: 2.0238988e+10 | AY2: 2.0537855e+10 | AZ2: 2.0726311e+10
A3: Albania | B3: GNI, Atlas method (current US$) | C3: 1714584896 | D3: 1745896523 | E3: 1784582564 | F3: 1798548685 | G3: 1814578498 | H3: 1832541547 | I3: 1845848968 | J3: 1854574874 | K3: 1865248547 | L3: 1874754821 | M3: 1895647847 | N3: 1915485986 | O3: 1947485965 | P3: 1974854745 | Q3: 1985985684 | R3: 2015487489 | S3: 2.1142905e+09 | T3: 2.2509466e+09 | U3: 2.3082594e+09 | V3: 2.4456693e+09 | W3: 2.1446746e+09 | X3: 1.3405949e+09 | Y3: 9.0618421e+08 | Z3: 1.0242631e+09 | AA3: 1.2166807e+09 | AB3: 2.0352202e+09 | AC3: 2.8240146e+09 | AD3: 2.5329105e+09 | AE3: 2.7013454e+09 | AF3: 2.9564122e+09 | AG3: 3.4087083e+09 | AH3: 3.927924e+09 | AI3: 4.1931533e+09 | AJ3: 5.0248953e+09 | AK3: 6.3668541e+09 | AL3: 7.8992134e+09 | AM3: 9.1312397e+09 | AN3: 1.0273337e+10 | AO3: 1.1883465e+10 | AP3: 1.2528133e+10 | AQ3: 1.2708645e+10 | AR3: 1.2803715e+10 | AS3: 1.2659043e+10 | AT3: 1.3156879e+10 | AU3: 1.3116565e+10 | AV3: 1.2634903e+10 | AW3: 1.2421239e+10 | AX3: 1.2331894e+10 | AY3: 1.393611e+10 | AZ3: 1.4948659e+10
