Workbook

Sheet Australia
A1: Australia Genuine Progress Indicator
B2: YEAR | C2: 1962 | D2: 1963 | E2: 1964 | F2: 1965 | G2: 1966 | H2: 1967 | I2: 1968 | J2: 1969 | K2: 1970 | L2: 1971 | M2: 1972 | N2: 1973 | O2: 1974 | P2: 1975 | Q2: 1976 | R2: 1977 | S2: 1978 | T2: 1979 | U2: 1980 | V2: 1981 | W2: 1982 | X2: 1983 | Y2: 1984 | Z2: 1985 | AA2: 1986 | AB2: 1987 | AC2: 1988 | AD2: 1989 | AE2: 1990 | AF2: 1991 | AG2: 1992 | AH2: 1993 | AI2: 1994 | AJ2: 1995 | AK2: 1996 | AL2: 1997 | AM2: 1998 | AN2: 1999 | AO2: 2000 | AP2: 2001 | AQ2: 2002 | AR2: 2003 | AS2: 2004 | AT2: 2005 | AU2: 2006 | AV2: 2007 | AW2: 2008 | AX2: 2009 | AY2: 2010 | AZ2: 2011 | BA2: 2012 | BB2: 2013 | BD2: operation | BF2: % Change
A3: A | B3: GPI (Billions 2012$) | C3: =C6+C7-C8-C9+C10-C11-C12-C13-C14-C15-C16-C17-C18-C19+C20-C21-C22-C23+C24-C25+C26+C27-C28-C29 -> 182.13067 | D3: =D6+D7-D8-D9+D10-D11-D12-D13-D14-D15-D16-D17-D18-D19+D20-D21-D22-D23+D24-D25+D26+D27-D28-D29 -> 179.37996 | E3: =E6+E7-E8-E9+E10-E11-E12-E13-E14-E15-E16-E17-E18-E19+E20-E21-E22-E23+E24-E25+E26+E27-E28-E29 -> 183.64015 | F3: =F6+F7-F8-F9+F10-F11-F12-F13-F14-F15-F16-F17-F18-F19+F20-F21-F22-F23+F24-F25+F26+F27-F28-F29 -> 190.51234 | G3: =G6+G7-G8-G9+G10-G11-G12-G13-G14-G15-G16-G17-G18-G19+G20-G21-G22-G23+G24-G25+G26+G27-G28-G29 -> 198.4139 | H3: =H6+H7-H8-H9+H10-H11-H12-H13-H14-H15-H16-H17-H18-H19+H20-H21-H22-H23+H24-H25+H26+H27-H28-H29 -> 208.19541 | I3: =I6+I7-I8-I9+I10-I11-I12-I13-I14-I15-I16-I17-I18-I19+I20-I21-I22-I23+I24-I25+I26+I27-I28-I29 -> 216.58006 | J3: =J6+J7-J8-J9+J10-J11-J12-J13-J14-J15-J16-J17-J18-J19+J20-J21-J22-J23+J24-J25+J26+J27-J28-J29 -> 229.45409 | K3: =K6+K7-K8-K9+K10-K11-K12-K13-K14-K16-K16-K17-K18-K19+K20-K21-K22-K23+K24-K25+K26+K27-K28-K29 -> 243.37589 | L3: =L6+L7-L8-L9+L10-L11-L12-L13-L14-L15-L16-L17-L18-L19+L20-L21-L22-L23+L24-L25+L26+L27-L28-L29 -> 249.27611 | M3: =M6+M7-M8-M9+M10-M11-M12-M13-M14-M15-M16-M17-M18-M19+M20-M21-M22-M23+M24-M25+M26+M27-M28-M29 -> 252.62767 | N3: =N6+N7-N8-N9+N10-N11-N12-N13-N14-N15-N16-N17-N18-N19+N20-N21-N22-N23+N24-N25+N26+N27-N28-N29 -> 266.39541 | O3: =O6+O7-O8-O9+O10-O11-O12-O13-O14-O15-O16-O17-O18-O19+O20-O21-O22-O23+O24-O25+O26+O27-O28-O29 -> 286.70859 | P3: =P6+P7-P8-P9+P10-P11-P12-P13-P14-P15-P16-P17-P18-P19+P20-P21-P22-P23+P24-P25+P26+P27-P28-P29 -> 304.85829 | Q3: =Q6+Q7-Q8-Q9+Q10-Q11-Q12-Q13-Q14-Q15-Q16-Q17-Q18-Q19+Q20-Q21-Q22-Q23+Q24-Q25+Q26+Q27-Q28-Q29 -> 320.04534 | R3: =R6+R7-R8-R9+R10-R11-R12-R13-R14-R15-R16-R17-R18-R19+R20-R21-R22-R23+R24-R25+R26+R27-R28-R29 -> 321.32309 | S3: =S6+S7-S8-S9+S10-S11-S12-S13-S14-S15-S16-S17-S18-S19+S20-S21-S22-S23+S24-S25+S26+S27-S28-S29 -> 334.53222 | ... BB3: =BB6+BB7-BB8-BB9+BB10-BB11-BB12-BB13-BB14-BB15-BB16-BB17-BB18-BB19+BB20-BB21-BB22-BB23+BB24-BB25+BB26+BB27-BB28-BB29 -> 798.44863 | BD3: total | BE3: GPI (Billions 2012$) | BF3: =((BB3-C3)/C3)*100 -> 338.39328
A4: 1 | B4: Personal Consumption Expenditures | C4: 139.75 | D4: 149.32 | E4: 157.61 | F4: 163.73 | G4: 169.37 | H4: 178.06 | I4: 188.79 | J4: 201.19 | K4: 214.51 | L4: 223.76 | M4: 232.11 | N4: 246.16 | O4: 259.98 | P4: 270.72 | Q4: 281.06 | R4: 284.89 | S4: 292.21 | T4: 297.01 | U4: 305.64 | V4: 319.31 | W4: 330.28 | X4: 332.01 | Y4: 341.88 | Z4: 356.46 | AA4: 363.62 | AB4: 370.48 | AC4: 383.81 | AD4: 400.49 | AE4: 407.29 | AF4: 414.11 | AG4: 429.31 | AH4: 437.98 | AI4: 452.07 | AJ4: 462.8 | AK4: 473.42 | AL4: 499.28 | AM4: 525.02 | AN4: 551 | AO4: 563.68 | AP4: 575.54 | AQ4: 599.01 | AR4: 620.07 | AS4: 649.77 | AT4: 667.23 | AU4: 692.79 | AV4: 737.87 | AW4: 743.84 | AX4: 756.04 | AY4: 775.59 | AZ4: 794.14 | BA4: 820.08 | BB4: 835.25 | BE4: Personal Consumption Expenditures | BF4: =((BB4-C4)/C4)*100 -> 497.67442
A5: 2 | B5: Income Inequality | C5: 1.182 | D5: 1.185 | E5: 1.17 | F5: 1.147 | G5: 1.129 | H5: 1.118 | I5: 1.115 | J5: 1.099 | K5: 1.085 | L5: 1.093 | M5: 1.096 | N5: 1.067 | O5: 1.029 | P5: 1.005 | Q5: 0.992 | R5: 0.985 | S5: 0.981 | T5: 0.981 | U5: 0.989 | V5: 0.992 | W5: 1 | X5: 1.02 | Y5: 1.041 | Z5: 1.061 | AA5: 1.081 | AB5: 1.069 | AC5: 1.057 | AD5: 1.045 | AE5: 1.033 | AF5: 1.054 | AG5: 1.074 | AH5: 1.094 | AI5: 1.115 | AJ5: 1.119 | AK5: 1.096 | AL5: 1.081 | AM5: 1.122 | AN5: 1.135 | AO5: 1.148 | AP5: 1.152 | AQ5: 1.148 | AR5: 1.144 | AS5: 1.133 | AT5: 1.148 | AU5: 1.163 | AV5: 1.204 | AW5: 1.244 | AX5: 1.231 | AY5: 1.219 | AZ5: 1.202 | BA5: 1.185 | BB5: 1.19 | BE5: Income Inequality | BF5: =((BB5-C5)/C5)*100 -> 0.67681895
A6: 3 | B6: Adjusted Personal Consumption | C6: 128.31 | D6: 136.82 | E6: 146.28 | F6: 154.88 | G6: 162.83 | H6: 172.86 | I6: 183.76 | J6: 198.65 | K6: 214.51 | L6: 222.2 | M6: 229.87 | N6: 250.49 | O6: 274.26 | P6: 292.26 | Q6: 307.43 | R6: 314.03 | S6: 323.32 | T6: 328.5 | U6: 335.5 | V6: 349.54 | W6: 358.51 | X6: 353.19 | Y6: 356.57 | Z6: 364.64 | AA6: 364.96 | AB6: 376.03 | AC6: 394 | AD6: 415.85 | AE6: 427.84 | AF6: 426.59 | AG6: 433.86 | AH6: 434.39 | AI6: 440.17 | AJ6: 449.13 | AK6: 468.74 | AL6: 501.12 | AM6: 507.83 | AN6: 526.87 | AO6: 532.91 | AP6: 542.37 | AQ6: 566.31 | AR6: 588.12 | AS6: 622.33 | AT6: 630.8 | AU6: 646.63 | AV6: 665.39 | AW6: 648.82 | AX6: 666.4 | AY6: 690.9 | AZ6: 717.24 | BA6: 751.08 | BB6: 763.43 | BD6: Start | BE6: Adjusted Personal Consumption | BF6: =((BB6-C6)/C6)*100 -> 494.9887
A7: 4 | B7: Services of Consumer Durables | C7: 4.8732 | D7: 5.2272 | E7: 5.6354 | F7: 6.0748 | G7: 6.6988 | H7: 7.5682 | I7: 8.645 | J7: 9.9308 | K7: 11.2858 | L7: 12.768 | M7: 14.3296 | N7: 16.1474 | O7: 18.1412 | P7: 20.18 | Q7: 22.293 | R7: 24.565 | S7: 27.3906 | T7: 30.2648 | U7: 33.3024 | V7: 36.7412 | W7: 40.4462 | X7: 44.296 | Y7: 47.636 | Z7: 50.9798 | AA7: 53.735 | AB7: 56.5878 | AC7: 59.6652 | AD7: 62.1982 | AE7: 64.4528 | AF7: 66.711 | AG7: 69.494 | AH7: 72.4672 | AI7: 75.7076 | AJ7: 79.6054 | AK7: 83.6214 | AL7: 87.9562 | AM7: 92.2358 | AN7: 96.4844 | AO7: 101.7198 | AP7: 106.0036 | AQ7: 109.8638 | AR7: 113.1916 | AS7: 115.8928 | AT7: 118.733 | AU7: 121.6172 | AV7: 121.6172 | AW7: 121.6172 | AX7: 121.6172 | AY7: 121.6172 | AZ7: 121.6172 | BA7: 121.6172 | BB7: 121.6172 | BD7: add | BE7: Services of Consumer Durables | BF7: =((BB7-C7)/C7)*100 -> 2395.6333
A8: 5 | B8: Cost of Consumer Durables | C8: 30.782051 | D8: 32.936709 | E8: 34.52439 | F8: 34.588235 | G8: 34.413793 | H8: 36.033333 | I8: 37.923913 | J8: 40.694737 | K8: 41.71 | L8: 43.392523 | M8: 44.892857 | N8: 48.095238 | O8: 49.938776 | P8: 51.35119 | Q8: 51.65625 | R8: 50.671429 | S8: 51.247788 | T8: 50.004016 | U8: 51.900735 | V8: 53.076159 | W8: 52.1875 | X8: 52.580822 | Y8: 56.893048 | Z8: 61.158025 | AA8: 58.452703 | AB8: 58.065126 | AC8: 61.154297 | AD8: 62.597826 | AE8: 62.345763 | AF8: 59.919866 | AG8: 63.222962 | AH8: 62.982026 | AI8: 64.039809 | AJ8: 65.190909 | AK8: 65.635821 | AL8: 68.603293 | AM8: 70.90708 | AN8: 72.079595 | AO8: 72.316005 | AP8: 72.608753 | AQ8: 76.940722 | AR8: 79.378616 | AS8: 80.552147 | AT8: 80.220764 | AU8: 80.04388 | AV8: 85.279461 | AW8: 80.391775 | AX8: 78.52386 | AY8: 78.78741 | AZ8: 76.765531 | BA8: 78.285294 | BB8: 77.906489 | BD8: subtract | BE8: Cost of Consumer Durables | BF8: =((BB8-C8)/C8)*100 -> 153.09063
A9: 6 | B9: Cost of Underemployment | C9: 0.99238185 | D9: 1.0124917 | E9: 1.0328043 | F9: 1.0669867 | G9: 1.1042033 | H9: 1.1498674 | I9: 1.2256203 | J9: 1.3233037 | K9: 1.4271257 | L9: 1.5549115 | M9: 1.6225214 | N9: 1.6563041 | O9: 1.7528244 | P9: 1.7383403 | Q9: 1.8099116 | R9: 1.8646111 | S9: 2.8137918 | T9: 2.8063495 | U9: 3.1938711 | V9: 3.2105155 | W9: 3.4984069 | X9: 4.4730629 | Y9: 4.3931848 | Z9: 4.0622244 | AA9: 4.4104829 | AB9: 5.0400316 | AC9: 4.6030622 | AD9: 5.1995193 | AE9: 5.8201694 | AF9: 7.9243097 | AG9: 10.142763 | AH9: 10.54298 | AI9: 10.407255 | AJ9: 10.364357 | AK9: 12.238495 | AL9: 13.262023 | AM9: 13.501438 | AN9: 13.324188 | AO9: 13.062228 | AP9: 13.974827 | AQ9: 14.602759 | AR9: 16.719707 | AS9: 16.309272 | AT9: 16.6241 | AU9: 16.893757 | AV9: 17.330366 | AW9: 16.888039 | AX9: 22.554747 | AY9: 21.657864 | AZ9: 23 | BA9: 25.541265 | BB9: 27.346914 | BD9: subtract | BE9: Cost of Underemployment | BF9: =((BB9-C9)/C9)*100 -> 2655.6846
A10: 7 | B10: Net Capital Investment | C10: 13.24 | D10: 13.5 | E10: 13.76 | F10: 14.04 | G10: 14.3 | H10: 14.54 | I10: 14.8 | J10: 15.12 | K10: 15.42 | L10: 16.11 | M10: 16.4 | N10: 16.65 | O10: 16.92 | P10: 17.13 | Q10: 17.3 | R10: 17.49 | S10: 17.7 | T10: 17.89 | U10: 18.11 | V10: 18.4 | W10: 18.72 | X10: 18.97 | Y10: 19.2 | Z10: 19.46 | AA10: 19.74 | AB10: 20.05 | AC10: 27.27 | AD10: 28.12 | AE10: 26.02 | AF10: 21.49 | AG10: 24.45 | AH10: 26.17 | AI10: 27.71 | AJ10: 29.45 | AK10: 33.13 | AL10: 32.59 | AM10: 35.01 | AN10: 36.73 | AO10: 39.52 | AP10: 46.16 | AQ10: 46.01 | AR10: 52.04 | AS10: 52.32 | AT10: 61.41 | AU10: 64.19 | AV10: 69.98 | AW10: 86.58 | AX10: 76.15 | AY10: 91.53 | AZ10: 102.24 | BA10: 99.9 | BB10: 105.19 | BD10: add | BE10: Net Capital Investment | BF10: =((BB10-C10)/C10)*100 -> 694.4864
A11: 8 | B11: Cost of Water Pollution | C11: 0.326 | D11: 0.343 | E11: 0.361 | F11: 0.379 | G11: 0.398 | H11: 0.419 | I11: 0.44 | J11: 0.462 | K11: 0.486 | L11: 0.511 | M11: 0.537 | N11: 0.564 | O11: 0.593 | P11: 0.623 | Q11: 0.655 | R11: 0.689 | S11: 0.724 | T11: 0.761 | U11: 0.8 | V11: 0.84 | W11: 0.883 | X11: 0.928 | Y11: 0.976 | Z11: 1.025 | AA11: 1.078 | AB11: 1.133 | AC11: 1.19 | AD11: 1.251 | AE11: 1.315 | AF11: 1.382 | AG11: 1.453 | AH11: 1.527 | AI11: 1.605 | AJ11: 1.687 | AK11: 1.773 | AL11: 1.863 | AM11: 1.958 | AN11: 2.058 | AO11: 2.163 | AP11: 2.273 | AQ11: 2.388 | AR11: 2.509 | AS11: 2.636 | AT11: 2.814 | AU11: 2.833 | AV11: 2.976 | AW11: 3.127 | AX11: 3.285 | AY11: 3.746 | AZ11: 3.936 | BA11: 4.132 | BB11: 4.344 | BD11: subtract | BE11: Cost of Water Pollution | BF11: =((BB11-C11)/C11)*100 -> 1232.5153
A12: 9 | B12: Cost of Air Pollution | C12: 3.92 | D12: 3.95 | E12: 3.97 | F12: 3.99 | G12: 4.01 | H12: 4.03 | I12: 4.05 | J12: 4.08 | K12: 4.11 | L12: 4.13 | M12: 4.15 | N12: 4.17 | O12: 4.19 | P12: 4.21 | Q12: 4.23 | R12: 4.26 | S12: 4.28 | T12: 4.3 | U12: 4.32 | V12: 4.35 | W12: 4.37 | X12: 4.39 | Y12: 4.41 | Z12: 4.44 | AA12: 4.46 | AB12: 4.48 | AC12: 4.5 | AD12: 4.53 | AE12: 4.55 | AF12: 4.58 | AG12: 4.6 | AH12: 4.62 | AI12: 4.65 | AJ12: 4.67 | AK12: 4.69 | AL12: 4.72 | AM12: 4.74 | AN12: 4.77 | AO12: 4.79 | AP12: 4.82 | AQ12: 4.84 | AR12: 4.87 | AS12: 4.89 | AT12: 4.92 | AU12: 4.94 | AV12: 4.97 | AW12: 5.19 | AX12: 4.52 | AY12: 5.06 | AZ12: 5.51 | BA12: 5.31 | BB12: 5.38 | BD12: subtract | BE12: Cost of Air Pollution | BF12: =((BB12-C12)/C12)*100 -> 37.244898
A13: 10 | B13: Cost of Noise Pollution | BD13: subtract | BE13: Cost of Noise Pollution | BF13: =((BB13-C13)/C13)*100 -> #DIV/0!
A14: 11 | B14: Cost of Net Wetland Change | BD14: subtract | BE14: Cost of Net Wetland Change | BF14: =((BB14-C14)/C14)*100 -> #DIV/0!
A15: 12 | B15: Cost of Net Farmland Change | C15: 0.28 | D15: 0.28 | E15: 0.28 | F15: 0.28 | G15: 0.29 | H15: 0.29 | I15: 0.29 | J15: 0.29 | K15: 0.29 | L15: 0.29 | M15: 0.29 | N15: 0.29 | O15: 0.29 | P15: 0.29 | Q15: 0.29 | R15: 0.29 | S15: 0.29 | T15: 0.29 | U15: 0.29 | V15: 0.29 | W15: 0.29 | X15: 0.29 | Y15: 0.29 | Z15: 0.29 | AA15: 0.29 | AB15: 0.28 | AC15: 0.28 | AD15: 0.27 | AE15: 0.27 | AF15: 0.27 | AG15: 0.27 | AH15: 0.27 | AI15: 0.28 | AJ15: 0.27 | AK15: 0.27 | AL15: 0.27 | AM15: 0.27 | AN15: 0.27 | AO15: 0.27 | AP15: 0.27 | AQ15: 0.26 | AR15: 0.26 | AS15: 0.26 | AT15: 0.26 | AU15: 0.26 | AV15: 0.25 | AW15: 0.24 | AX15: 0.24 | AY15: 0.23 | AZ15: 0.24 | BA15: 0.24 | BB15: 0.23 | BD15: subtract | BE15: Cost of Net Farmland Change | BF15: =((BB15-C15)/C15)*100 -> -17.857143
A16: 13 | B16: Cost of Net Forest Cover Change | N16: 2.43 | O16: 4.09 | P16: 3.87 | Q16: 2.66 | R16: 2.29 | S16: 2.43 | T16: 2.47 | U16: 3.44 | V16: 3.65 | W16: 3.64 | X16: 3.64 | Y16: 3.35 | Z16: 2.05 | AA16: 2 | AB16: 2.05 | AC16: 1.67 | AD16: 1.46 | AE16: 1.28 | AF16: 0.7 | AG16: 0.94 | AH16: 1.1 | AI16: 1.02 | AJ16: 1.17 | AK16: 1.23 | AL16: 1.21 | AM16: 1.32 | AN16: 1.32 | AO16: 1 | AP16: 0.94 | AQ16: 0.24 | AR16: 0.13 | AS16: 0.43 | BD16: subtract | BE16: Cost of Net Forest Cover Change | BF16: =((BB16-C16)/C16)*100 -> #DIV/0!
A17: 14 | B17: Cost of Climate Change | C17: 34.51 | D17: 37.11 | E17: 39.72 | F17: 42.32 | G17: 44.93 | H17: 47.53 | I17: 50.14 | J17: 52.74 | K17: 55.35 | L17: 58.66 | M17: 60.62 | N17: 64.53 | O17: 70.53 | P17: 73.27 | Q17: 74.25 | R17: 80.07 | S17: 78.25 | T17: 80.7 | U17: 84.66 | V17: 84.79 | W17: 87.31 | X17: 82.42 | Y17: 85.05 | Z17: 89.95 | AA17: 90.4 | AB17: 94.42 | AC17: 98.53 | AD17: 103.92 | AE17: 106.01 | AF17: 106.57 | AG17: 108.08 | AH17: 109.71 | AI17: 112.2 | AJ17: 116.39 | AK17: 120.56 | AL17: 123.61 | AM17: 131.51 | AN17: 134.04 | AO17: 136.49 | AP17: 139.16 | AQ17: 141.04 | AR17: 143.96 | AS17: 149.84 | AT17: 151.37 | AU17: 153.14 | AV17: 157.22 | AW17: 158.27 | AX17: 160.84 | AY17: 157.63 | AZ17: 158.05 | BA17: 157.21 | BB17: 175.15 | BD17: subtract | BE17: Cost of Climate Change | BF17: =((BB17-C17)/C17)*100 -> 407.53405
A18: 15 | B18: Cost of Ozone Depletion | C18: 0 | D18: 0 | E18: 0 | F18: 0 | G18: 0 | H18: 0 | I18: 0 | J18: 0 | K18: 0 | L18: 0 | M18: 0 | N18: 0 | O18: 0 | P18: 0 | Q18: 0 | R18: 0 | S18: 0 | T18: 0 | U18: 19.12 | V18: 19.78 | W18: 20.42 | X18: 21.03 | Y18: 21.63 | Z18: 22.2 | AA18: 22.74 | AB18: 23.27 | AC18: 23.77 | AD18: 24.25 | AE18: 24.7 | AF18: 25.14 | AG18: 25.55 | AH18: 25.94 | AI18: 26.3 | AJ18: 26.82 | AK18: 27.14 | AL18: 27.39 | AM18: 27.63 | AN18: 27.83 | AO18: 28.01 | AP18: 28.15 | AQ18: 28.3 | AR18: 28.43 | AS18: 28.56 | AT18: 28.69 | AU18: 28.82 | AV18: 28.97 | AW18: 29.1 | AX18: 29.21 | AY18: 29.29 | AZ18: 29.38 | BA18: 29.46 | BB18: 29.53 | BD18: subtract | BE18: Cost of Ozone Depletion | BF18: =((BB18-U18)/U18)*100 -> 54.445607
A19: 16 | B19: Cost of Nonrenewable Energy Resource Depletion | C19: 4.9 | D19: 6.79 | E19: 8.68 | F19: 10.57 | G19: 12.47 | H19: 14.36 | I19: 16.25 | J19: 18.14 | K19: 20.03 | L19: 21.93 | M19: 23.82 | N19: 25.71 | O19: 27.6 | P19: 29.5 | Q19: 31.39 | R19: 35.09 | S19: 36.67 | T19: 38.34 | U19: 41.26 | V19: 42.23 | W19: 45.34 | X19: 44.3 | Y19: 45.76 | Z19: 48.38 | AA19: 48.29 | AB19: 50.79 | AC19: 52.28 | AD19: 56.6 | AE19: 57.87 | AF19: 57.71 | AG19: 59.72 | AH19: 59.42 | AI19: 60.2 | AJ19: 63.2 | AK19: 65.73 | AL19: 67.09 | AM19: 72.5 | AN19: 75.98 | AO19: 77.18 | AP19: 81.16 | AQ19: 84.29 | AR19: 84.03 | AS19: 88.98 | AT19: 91.17 | AU19: 92.76 | AV19: 96.93 | AW19: 97.77 | AX19: 103.55 | AY19: 95.39 | AZ19: 92.74 | BA19: 94.69 | BB19: 88.64 | BD19: subtract | BE19: Cost of Nonrenewable Energy Resource Depletion | BF19: =((BB19-C19)/C19)*100 -> 1708.9796
A20: 17 | B20: Value of Housework | C20: 175.545 | D20: 178.37521 | E20: 181.40621 | F20: 184.75457 | G20: 188.75818 | H20: 192.92826 | I20: 197.21068 | J20: 201.76634 | K20: 205.96289 | L20: 215.27368 | M20: 219.40979 | N20: 223.44436 | O20: 228.38629 | P20: 232.95283 | Q20: 237.86332 | R20: 241.5117 | S20: 244.85581 | T20: 247.55091 | U20: 250.18593 | V20: 252.93758 | W20: 256.30547 | X20: 259.05608 | Y20: 261.81563 | Z20: 265.16361 | AA20: 269.54915 | AB20: 274.19558 | AC20: 278.91359 | AD20: 283.61687 | AE20: 287.57676 | AF20: 290.66506 | AG20: 292.26826 | AH20: 293.12067 | AI20: 294.27077 | AJ20: 296.00657 | AK20: 298.26512 | AL20: 300.16595 | AM20: 301.8896 | AN20: 303.83801 | AO20: 305.9156 | AP20: 308.33003 | AQ20: 310.35745 | AR20: 312.38467 | AS20: 314.19119 | AT20: 316.49787 | AU20: 319.2542 | AV20: 323.34732 | AW20: 328.082 | AX20: 333.14397 | AY20: 336.68059 | AZ20: 339.94789 | BA20: 343.59233 | BB20: 351.8043 | BD20: add | BE20: Value of Housework | BF20: =((BB20-C20)/C20)*100 -> 100.40691
A21: 18 | B21: Cost of Family Changes | C21: 3.5637939 | D21: 3.6565554 | E21: 3.7553655 | F21: 3.8676092 | G21: 4.0027814 | H21: 4.1915424 | I21: 4.3308949 | J21: 4.476816 | K21: 4.6274716 | L21: 4.7888331 | M21: 4.9714443 | N21: 5.1511125 | O21: 5.3022031 | P21: 5.5815087 | Q21: 6.0577208 | R21: 6.551768 | S21: 6.5571081 | T21: 6.5555204 | U21: 6.6584824 | V21: 6.8477426 | W21: 7.0482507 | X21: 7.2010028 | Y21: 7.2996338 | Z21: 7.3502276 | AA21: 7.3933661 | AB21: 7.5607664 | AC21: 7.7281667 | AD21: 7.895567 | AE21: 8.0629673 | AF21: 8.2303676 | AG21: 8.4227835 | AH21: 8.6708326 | AI21: 8.82446 | AJ21: 9.0291138 | AK21: 9.2813828 | AL21: 9.3907452 | AM21: 9.5444172 | AN21: 9.7372645 | AO21: 9.7945103 | AP21: 10.136041 | AQ21: 10.210782 | AR21: 10.301946 | AS21: 10.409322 | AT21: 10.518456 | AU21: 10.62752 | AV21: 10.771095 | AW21: 10.81842 | AX21: 11.014011 | AY21: 11.208055 | AZ21: 11.330218 | BA21: 11.535797 | BB21: 11.629744 | BD21: subtract | BE21: Cost of Family Changes | BF21: =((BB21-C21)/C21)*100 -> 226.33044
A22: 19 | B22: Cost of Crime | C22: 1.3 | D22: 1.59 | E22: 1.88 | F22: 2.03 | G22: 2.35 | H22: 2.52 | I22: 2.82 | J22: 3 | K22: 3.59 | L22: 4.06 | M22: 4.26 | N22: 4.08 | O22: 4.37 | P22: 4.67 | Q22: 4.58 | R22: 4.81 | S22: 5.38 | T22: 5.88 | U22: 6.18 | V22: 6.27 | W22: 6.9 | X22: 7.88 | Y22: 7.7 | Z22: 7.51 | AA22: 7.27 | AB22: 8.06 | AC22: 7.92 | AD22: 8.25 | AE22: 8.59 | AF22: 8.85 | AG22: 9.03 | AH22: 9.2 | AI22: 8.98 | AJ22: 8.9 | AK22: 9.02 | AL22: 10.1 | AM22: 10.76 | AN22: 11.1 | AO22: 10.98 | AP22: 11.3 | AQ22: 10.45 | AR22: 10.23 | AS22: 8.72 | AT22: 8.43 | AU22: 8.21 | AV22: 7.85 | AW22: 7.64 | AX22: 7.53 | AY22: 7.09 | AZ22: 6.19 | BA22: 6.05 | BD22: subtract | BE22: Cost of Crime | BF22: =((BB22-C22)/C22)*100 -> -100
A23: 20 | B23: Cost of Personal Pollution Abatement | BD23: subtract | BE23: Cost of Personal Pollution Abatement | BF23: =((BB23-C23)/C23)*100 -> #DIV/0!
A24: 21 | B24: Value of Volunteer Work | C24: 20.3642 | D24: 20.7714 | E24: 21.1869 | F24: 21.6106 | G24: 22.0428 | H24: 22.4837 | I24: 22.9333 | J24: 23.392 | K24: 23.8599 | L24: 24.337 | M24: 24.8238 | N24: 25.3203 | O24: 25.8267 | P24: 26.3432 | Q24: 26.8701 | R24: 27.4075 | S24: 27.9556 | T24: 28.5147 | U24: 29.085 | V24: 29.6667 | W24: 30.2601 | X24: 30.8653 | Y24: 31.4826 | Z24: 32.1122 | AA24: 32.7545 | AB24: 33.4096 | AC24: 34.0777 | AD24: 34.7593 | AE24: 35.4545 | AF24: 36.1636 | AG24: 36.8868 | AH24: 38.4395 | AI24: 39.9922 | AJ24: 41.5449 | AK24: 43.0976 | AL24: 44.6503 | AM24: 45.5433 | AN24: 46.4542 | AO24: 47.3833 | AP24: 48.331 | AQ24: 49.2976 | AR24: 50.2835 | AS24: 51.2892 | AT24: 52.315 | AU24: 53.3613 | AV24: 54.4285 | AW24: 55.5171 | AX24: 56.6274 | AY24: 57.76 | AZ24: 58.9152 | BA24: 60.0935 | BB24: 61.2953 | BD24: add | BE24: Value of Volunteer Work | BF24: =((BB24-C24)/C24)*100 -> 200.99537
A25: 22 | B25: Cost of Lost Leisure Time | C25: 1e-19 | D25: 0 | E25: 0 | F25: 0 | G25: 0 | H25: 0 | I25: 0 | J25: 0 | K25: 0 | L25: 0 | M25: 0 | N25: 0 | O25: 0 | P25: 0 | Q25: 0 | R25: 0 | S25: 0 | T25: 0 | U25: 2.8140492 | V25: 1.378705 | W25: -1.861521 | X25: -5.1372513 | Y25: -1.8203469 | Z25: -3.4205995 | AA25: -1.5673242 | AB25: -0.79586296 | AC25: 4.1367744 | AD25: 5.7640958 | AE25: 3.7064031 | AF25: -0.02899841 | AG25: 4.2328711 | AH25: 4.8694344 | AI25: 7.5150258 | AJ25: 9.6263073 | AK25: 6.7789422 | AL25: 5.0597694 | AM25: 5.0530431 | AN25: 2.1653502 | AO25: 7.176153 | AP25: -2.6266069 | AQ25: -5.38958 | AR25: -4.7029926 | AS25: -6.3082238 | AT25: -10.040662 | AU25: -14.015389 | AV25: -18.303553 | AW25: -21.77998 | AX25: -23.862464 | AY25: -27.496971 | AZ25: -28.410499 | BA25: -28.952517 | BB25: -38.917473 | BD25: subtract | BE25: Cost of Lost Leisure Time | BF25: =((BB25-U25)/U25)*100 -> -1482.9706
A26: 23 | B26: Value of Higher Education | C26: 0.02 | D26: 0.02 | E26: 0.03 | F26: 0.03 | G26: 0.03 | H26: 0.04 | I26: 0.04 | J26: 0.05 | K26: 0.05 | L26: 0.06 | M26: 0.07 | N26: 0.08 | O26: 0.08 | P26: 0.09 | Q26: 0.11 | R26: 0.12 | S26: 0.13 | T26: 0.15 | U26: 0.17 | V26: 0.18 | W26: 0.32 | X26: 0.32 | Y26: 0.32 | Z26: 0.85 | AA26: 0.89 | AB26: 1.07 | AC26: 1.23 | AD26: 1.43 | AE26: 1.56 | AF26: 1.71 | AG26: 1.87 | AH26: 1.7 | AI26: 1.73 | AJ26: 2.15 | AK26: 2.38 | AL26: 2.56 | AM26: 2.78 | AN26: 3 | AO26: 3.14 | AP26: 3.46 | AQ26: 3.63 | AR26: 3.75 | AS26: 3.98 | AT26: 4.15 | AU26: 4.39 | AV26: 4.53 | AW26: 4.88 | AX26: 5.23 | AY26: 5.38 | AZ26: 5.69 | BA26: 6.1 | BB26: 6.16 | BD26: add | BE26: Value of Higher Education | BF26: =((BB26-C26)/C26)*100 -> 30700
A27: 24 | B27: Services of Highways and Streets | BD27: add | BE27: Services of Highways and Streets | BF27: =((BB27-C27)/C27)*100 -> #DIV/0!
A28: 25 | B28: Cost of Commuting | C28: 60.43 | D28: 67.97 | E28: 67.97 | F28: 67.8 | G28: 67.7 | H28: 67.7 | I28: 67.7 | J28: 67.7 | K28: 67.59 | L28: 74.94 | M28: 81.17 | N28: 81.17 | O28: 81.17 | P28: 80.99 | Q28: 87.08 | R28: 90.09 | S28: 90.09 | T28: 93.75 | U28: 103.61 | V28: 104.04 | W28: 112.51 | X28: 116.01 | Y28: 116.88 | Z28: 121.41 | AA28: 125.19 | AB28: 126.33 | AC28: 130.5 | AD28: 136.44 | AE28: 136.24 | AF28: 139.62 | AG28: 142.16 | AH28: 145.41 | AI28: 149.05 | AJ28: 152.63 | AK28: 155.8 | AL28: 160.69 | AM28: 165.46 | AN28: 168.46 | AO28: 174.78 | AP28: 172.69 | AQ28: 177.21 | AR28: 182.25 | AS28: 186.32 | AT28: 191.19 | AU28: 195.78 | AV28: 202 | AW28: 205.25 | AX28: 206.52 | AY28: 212.29 | AZ28: 214.04 | BA28: 217.92 | BB28: 220.81 | BD28: subtract | BE28: Cost of Commuting | BF28: =((BB28-C28)/C28)*100 -> 265.39798
A29: 26 | B29: Cost of Motor Vehicle Crashes | C29: 19.2175 | D29: 19.6951 | E29: 22.4848 | F29: 23.9858 | G29: 24.5771 | H29: 24.001 | I29: 25.6385 | J29: 26.5482 | K29: 28.7921 | L29: 27.2153 | M29: 25.9417 | N29: 27.89 | O29: 27.0788 | P29: 28.0037 | Q29: 27.1622 | R29: 27.1243 | S29: 28.0871 | T29: 26.5936 | U29: 20.2879 | V29: 20.4586 | W29: 19.7874 | X29: 17.4234 | Y29: 17.8571 | Z29: 18.3721 | AA29: 18.1811 | AB29: 17.9826 | AC29: 18.3456 | AD29: 17.6906 | AE29: 15.1179 | AF29: 13.6732 | AG29: 12.9195 | AH29: 12.8676 | AI29: 12.9693 | AJ29: 13.322 | AK29: 13.0561 | AL29: 13.3954 | AM29: 13.3044 | AN29: 13.3726 | AO29: 14.1314 | AP29: 14.0392 | AQ29: 14.115 | AR29: 13.9727 | AS29: 13.9917 | AT29: 15.1758 | AU29: 15.1094 | AV29: 15.2076 | AW29: 14.9908 | AX29: 15.8119 | AY29: 14.493 | AZ29: 14.6633 | BA29: 9.8551 | BB29: 8.9985 | BD29: subtract | BE29: Cost of Motor Vehicle Crashes | BF29: =((BB29-C29)/C29)*100 -> -53.175491
B30: YEAR | C30: 1962 | D30: 1963 | E30: 1964 | F30: 1965 | G30: 1966 | H30: 1967 | I30: 1968 | J30: 1969 | K30: 1970 | L30: 1971 | M30: 1972 | N30: 1973 | O30: 1974 | P30: 1975 | Q30: 1976 | R30: 1977 | S30: 1978 | T30: 1979 | U30: 1980 | V30: 1981 | W30: 1982 | X30: 1983 | Y30: 1984 | Z30: 1985 | AA30: 1986 | AB30: 1987 | AC30: 1988 | AD30: 1989 | AE30: 1990 | AF30: 1991 | AG30: 1992 | AH30: 1993 | AI30: 1994 | AJ30: 1995 | AK30: 1996 | AL30: 1997 | AM30: 1998 | AN30: 1999 | AO30: 2000 | AP30: 2001 | AQ30: 2002 | AR30: 2003 | AS30: 2004 | AT30: 2005 | AU30: 2006 | AV30: 2007 | AW30: 2008 | AX30: 2009 | AY30: 2010 | AZ30: 2011 | BA30: 2012 | BB30: 2013 | BD30: operation | BF30: % Change
A31: B | B31: Economic Elements | C31: =C6+C7-C8-C9+C10 -> 114.64877 | D31: =D6+D7-D8-D9+D10 -> 121.598 | E31: =E6+E7-E8-E9+E10 -> 130.11821 | F31: =F6+F7-F8-F9+F10 -> 139.33958 | G31: =G6+G7-G8-G9+G10 -> 148.3108 | H31: =H6+H7-H8-H9+H10 -> 157.785 | I31: =I6+I7-I8-I9+I10 -> 168.05547 | J31: =J6+J7-J8-J9+J10 -> 181.68276 | ... BB31: =BB6+BB7-BB8-BB9+BB10 -> 884.9838
B32: Percent Change from Previous Year | D32: =(D31-C31)/C31 -> 0.060613234 | E32: =(E31-D31)/D31 -> 0.070068636 | F32: =(F31-E31)/E31 -> 0.070869196 | G32: =(G31-F31)/F31 -> 0.064383901 | H32: =(H31-G31)/G31 -> 0.063880684 | I32: =(I31-H31)/H31 -> 0.065091533 | J32: =(J31-I31)/I31 -> 0.081088066 | K32: =(K31-J31)/J31 -> 0.090244748 | ... BB32: =(BB31-BA31)/BA31 -> 0.018662182
A33: C | B33: Environmental Elements | C33: =C18-C19-C20-C21+C22+C24-C23+C25-C26-C27 -> -162.36459 | D33: =D18-D19-D20-D21+D22+D24-D23+D25-D26-D27 -> -166.48037 | E33: =E18-E19-E20-E21+E22+E24-E23+E25-E26-E27 -> -170.80468 | F33: =F18-F19-F20-F21+F22+F24-F23+F25-F26-F27 -> -175.58158 | G33: =G18-G19-G20-G21+G22+G24-G23+G25-G26-G27 -> -180.86816 | H33: =H18-H19-H20-H21+H22+H24-H23+H25-H26-H27 -> -186.5161 | I33: =I18-I19-I20-I21+I22+I24-I23+I25-I26-I27 -> -192.07828 | J33: =J18-J19-J20-J21+J22+J24-J23+J25-J26-J27 -> -198.04116 | ... BB33: =BB18-BB19-BB20-BB21+BB22+BB24-BB23+BB25-BB26-BB27 -> -406.32622
B34: Percent Change from Previous Year | D34: =(D33-C33)/C33 -> 0.025348979 | E34: =(E33-D33)/D33 -> 0.025974894 | F34: =(F33-E33)/E33 -> 0.027967058 | G34: =(G33-F33)/F33 -> 0.030108937 | H34: =(H33-G33)/G33 -> 0.031226841 | I34: =(I33-H33)/H33 -> 0.029821447 | J34: =(J33-I33)/I33 -> 0.031044006 | K34: =(K33-J33)/J33 -> 0.026152661 | ... BB34: =(BB33-BA33)/BA33 -> 0.043823577
A35: D | B35: Social Elements | C35: =C20-C21-C22-C23+C24+C26-C25+C27-C28-C29 -> 111.4179 | D35: =D20-D21-D22-D23+D24+D26-D25+D27-D28-D29 -> 106.25496 | E35: =E20-E21-E22-E23+E24+E26-E25+E27-E28-E29 -> 106.53295 | F35: =F20-F21-F22-F23+F24+F26-F25+F27-F28-F29 -> 108.71176 | G35: =G20-G21-G22-G23+G24+G26-G25+G27-G28-G29 -> 112.2011 | H35: =H20-H21-H22-H23+H24+H26-H25+H27-H28-H29 -> 117.03941 | I35: =I20-I21-I22-I23+I24+I26-I25+I27-I28-I29 -> 119.69459 | J35: =J20-J21-J22-J23+J24+J26-J25+J27-J28-J29 -> 123.48333 | ... BB35: =BB20-BB21-BB22-BB23+BB24+BB26-BB25+BB27-BB28-BB29 -> 216.73883
B36: Percent Change from Previous Year | D36: =(D35-C35)/C35 -> -0.046338571 | E36: =(E35-D35)/D35 -> 0.0026162507 | F36: =(F35-E35)/E35 -> 0.020452049 | G36: =(G35-F35)/F35 -> 0.032097083 | H36: =(H35-G35)/G35 -> 0.043121853 | I36: =(I35-H35)/H35 -> 0.022686161 | J36: =(J35-I35)/I35 -> 0.031653369 | K36: =(K35-J35)/J35 -> 0.01449501 | ... BB36: =(BB35-BA35)/BA35 -> 0.12080718
A37: A | B37: Genuine Progress Indicator | C37: =C31+C33+C35 -> 63.702079 | D37: =D31+D33+D35 -> 61.372589 | E37: =E31+E33+E35 -> 65.846474 | F37: =F31+F33+F35 -> 72.46976 | G37: =G31+G33+G35 -> 79.643741 | H37: =H31+H33+H35 -> 88.308314 | I37: =I31+I33+I35 -> 95.671777 | J37: =J31+J33+J35 -> 107.12493 | ... BB37: =BB31+BB33+BB35 -> 695.39641
B38: Genuine Progress Indicator - Double Check | C38: =C3-C37 -> 118.42859 | D38: =D3-D37 -> 118.00737 | E38: =E3-E37 -> 117.79368 | F38: =F3-F37 -> 118.04258 | G38: =G3-G37 -> 118.77016 | H38: =H3-H37 -> 119.8871 | I38: =I3-I37 -> 120.90828 | J38: =J3-J37 -> 122.32916 | ... BB38: =BB3-BB37 -> 103.05222
A40: E | B40: GDP (Adjusted for 2012$) | C40: 227.65385 | D40: 243 | E40: 259 | F40: 272.38824 | G40: 279.72414 | H40: 301.43333 | I40: 316.8587 | J40: 344.11579 | K40: 368.34 | L40: 376.57944 | M40: 396.94643 | N40: 394.5873 | O40: 409.82313 | P40: 423.24405 | Q40: 433.14583 | R40: 457.1381 | S40: 463.84956 | T40: 475.88353 | U40: 493.88603 | V40: 503.53974 | W40: 522.42857 | X40: 517.94247 | Y40: 570.5 | Z40: 580.11605 | AA40: 586.11261 | AB40: 600.39496 | AC40: 632.94141 | AD40: 666.27717 | AE40: 684.86949 | AF40: 692.65442 | AG40: 703.83527 | AH40: 725.61928 | AI40: 743.17675 | AJ40: 750.98939 | AK40: 789.63881 | AL40: 833.31737 | AM40: 868.32596 | AN40: 897.64834 | AO40: 903.94528 | AP40: 935.37798 | AQ40: 970.99485 | AR40: 1007.4176 | AS40: 1057.1472 | AT40: 1100.5716 | AU40: 1152.388 | AV40: 1220.009 | AW40: 1275.3485 | AX40: 1334.1188 | AY40: 1337.1796 | AZ40: 1410.6864 | BA40: 1458.851 | BB40: 1451.2824
B41: GDP: Percent Change from Previous Year | C41: =(C40-#REF!)/#REF! -> #REF! | D41: =(D40-C40)/C40 -> 0.067410035 | E41: =(E40-D40)/D40 -> 0.065843621 | F41: =(F40-E40)/E40 -> 0.051692028 | G41: =(G40-F40)/F40 -> 0.026931789 | H41: =(H40-G40)/G40 -> 0.077609303 | I41: =(I40-H40)/H40 -> 0.05117338 | J41: =(J40-I40)/I40 -> 0.086022868 | K41: =(K40-J40)/J40 -> 0.070395522 | ... BB41: =(BB40-BA40)/BA40 -> -0.0051880124
...

Sheet Sensitivity
A1: Sensitivity Analysis
B2: YEAR | C2: 1990 | D2: 2000 | E2: 2010 | G2: 1990 | L2: 2000 | Q2: 2010
B3: GPI (Billions 2012$) | C3: =C6+C7-C8-C9+C10-C11-C12-C13-C14-C15-C16-C17-C18-C19+C20-C21-C22-C23+C24-C25+C26+C27-C28-C29 -> 407.02586 | D3: =D6+D7-D8-D9+D10-D11-D12-D13-D14-D15-D16-D17-D18-D19+D20-D21-D22-D23+D24-D25+D26+D27-D28-D29 -> 478.4454 | E3: =E6+E7-E8-E9+E10-E11-E12-E13-E14-E15-E16-E17-E18-E19+E20-E21-E22-E23+E24-E25+E26+E27-E28-E29 -> 694.49243 | G3: Adjusted Personal Consumption | L3: Adjusted Personal Consumption | Q3: Adjusted Personal Consumption
B4: Personal Consumption Expenditures | C4: 407.29 | D4: 563.68 | E4: 775.59 | I4: GPI | J4: % Change | N4: GPI | O4: % Change | S4: GPI | T4: % Change
B5: Income Inequality | C5: 1.033 | D5: 1.148 | E5: 1.219 | I5: =C3 -> 407.02586 | N5: =D3 -> 478.4454 | S5: =E3 -> 694.49243
A6: * | B6: Adjusted Personal Consumption | C6: 427.84 | D6: 532.91 | E6: 690.9 | G6: 0.8 | H6: =0.8*H8 -> 342.272 | I6: 321.45786 | J6: =(I6-I8)/I8 -> -0.21022743 | L6: 0.8 | M6: =0.8*M8 -> 426.328 | N6: 371.8634 | O6: =(N6-N8)/N8 -> -0.22276732 | Q6: 0.8 | R6: =0.8*R8 -> 552.72 | S6: 556.31243 | T6: =(S6-S8)/S8 -> -0.19896545
B7: Services of Consumer Durables | C7: 64.4528 | D7: 101.7198 | E7: 121.6172 | G7: 0.9 | H7: =0.9*H8 -> 385.056 | I7: 364.24186 | J7: =(I7-I8)/I8 -> -0.10511371 | L7: 0.9 | M7: =0.9*M8 -> 479.619 | N7: 425.1544 | O7: =(N7-N8)/N8 -> -0.11138366 | Q7: 0.9 | R7: =0.9*R8 -> 621.81 | S7: 625.40243 | T7: =(S7-S8)/S8 -> -0.099482726
B8: Cost of Consumer Durables | C8: 62.345763 | D8: 72.316005 | E8: 78.78741 | G8: 1 | H8: 427.84 | I8: 407.02586 | J8: 0 | L8: 1 | M8: 532.91 | N8: 478.4454 | O8: 0 | Q8: 1 | R8: 690.9 | S8: 694.49243 | T8: 0
B9: Cost of Underemployment | C9: 5.8201694 | D9: 13.062228 | E9: 21.657864 | G9: 1.1 | H9: =1.1*H8 -> 470.624 | I9: 449.80986 | J9: =(I9-I8)/I8 -> 0.10511371 | L9: 1.1 | M9: =1.1*M8 -> 586.201 | N9: 531.7364 | O9: =(N9-N8)/N8 -> 0.11138366 | Q9: 1.1 | R9: =1.1*R8 -> 759.99 | S9: 763.58243 | T9: =(S9-S8)/S8 -> 0.099482726
B10: Net Capital Investment | C10: 26.02 | D10: 39.52 | E10: 91.53 | G10: 1.2 | H10: =1.2*H8 -> 513.408 | I10: 492.59386 | J10: =(I10-I8)/I8 -> 0.21022743 | L10: 1.2 | M10: =1.2*M8 -> 639.492 | N10: 585.0274 | O10: =(N10-N8)/N8 -> 0.22276732 | Q10: 1.2 | R10: =1.2*R8 -> 829.08 | S10: 832.67243 | T10: =(S10-S8)/S8 -> 0.19896545
B11: Cost of Water Pollution | C11: 1.315 | D11: 2.163 | E11: 3.746
A12: * | B12: Cost of Air Pollution | C12: 4.55 | D12: 4.79 | E12: 5.06 | G12: Cost of Climate Change | L12: Cost of Climate Change | Q12: Cost of Climate Change
B13: Cost of Noise Pollution | I13: GPI | J13: %Change | N13: GPI | O13: %Change | S13: GPI | T13: %Change
B14: Cost of Net Wetland Change | I14: =C3 -> 407.02586 | N14: =D3 -> 478.4454 | S14: =E3 -> 694.49243
B15: Cost of Net Farmland Change | C15: 0.27 | D15: 0.27 | E15: 0.23 | G15: 0.8 | H15: 84.808 | I15: 428.22786 | J15: =(I15-I17)/I17 -> 0.052090056 | L15: 0.8 | M15: =0.8*M17 -> 109.192 | N15: 505.7434 | O15: =(N15-N17)/N17 -> 0.057055622 | Q15: 0.8 | R15: =0.8*R17 -> 126.104 | S15: 726.01843 | T15: =(S15-S17)/S17 -> 0.045394303
B16: Cost of Net Forest Cover Change | C16: 1.28 | D16: 1 | G16: 0.9 | H16: 95.409 | I16: 417.62686 | J16: =(I16-I17)/I17 -> 0.026045028 | L16: 0.9 | M16: =0.9*M17 -> 122.841 | N16: 492.0944 | O16: =(N16-N17)/N17 -> 0.028527811 | Q16: 0.9 | R16: =0.9*R17 -> 141.867 | S16: 710.25543 | T16: =(S16-S17)/S17 -> 0.022697152
B17: Cost of Climate Change | C17: 106.01 | D17: 136.49 | E17: 157.63 | G17: 1 | H17: 106.01 | I17: 407.02586 | J17: 0 | L17: 1 | M17: 136.49 | N17: 478.4454 | O17: 0 | Q17: 1 | R17: 157.63 | S17: 694.49243 | T17: 0
B18: Cost of Ozone Depletion | C18: 24.7 | D18: 28.01 | E18: 29.29 | G18: 1.1 | H18: 116.611 | I18: 396.42486 | J18: =(I18-I17)/I17 -> -0.026045028 | L18: 1.1 | M18: =1.1*M17 -> 150.139 | N18: 464.7964 | O18: =(N18-N17)/N17 -> -0.028527811 | Q18: 1.1 | R18: =1.1*R17 -> 173.393 | S18: 678.72943 | T18: =(S18-S17)/S17 -> -0.022697152
A19: * | B19: Cost of Nonrenewable Energy Resource Depletion | C19: 57.87 | D19: 77.18 | E19: 95.39 | G19: 1.2 | H19: 127.212 | I19: 385.82386 | J19: =(I19-I17)/I17 -> -0.052090056 | L19: 1.2 | M19: =1.2*M17 -> 163.788 | N19: 451.1474 | O19: =(N19-N17)/N17 -> -0.057055622 | Q19: 1.2 | R19: =1.2*R17 -> 189.156 | S19: 662.96643 | T19: =(S19-S17)/S17 -> -0.045394303
A20: * | B20: Value of Housework | C20: 287.57676 | D20: 305.9156 | E20: 336.68059
A21: * | B21: Cost of Family Changes | C21: 8.0629673 | D21: 9.7945103 | E21: 11.208055 | G21: Value of Housework | L21: Value of Housework | Q21: Value of Housework
B22: Cost of Crime | C22: 8.59 | D22: 10.98 | E22: 7.09 | I22: GPI | J22: %Change | N22: GPI | O22: %Change | S22: GPI | T22: %Change
B23: Cost of Personal Pollution Abatement | I23: =C3 -> 407.02586 | N23: =D3 -> 478.4454 | S23: =E3 -> 694.49243
B24: Value of Volunteer Work | C24: 35.4545 | D24: 47.3833 | E24: 57.76 | G24: 0.8 | H24: 230.06141 | I24: 349.51051 | J24: =(I24-I26)/I26 -> -0.14130638 | L24: 0.8 | M24: =0.8*M26 -> 244.73248 | N24: 417.26228 | O24: =(N24-N26)/N26 -> -0.127879 | Q24: 0.8 | R24: =0.8*R26 -> 269.34447 | S24: 627.15631 | T24: =(S24-S26)/S26 -> -0.09695731
B25: Cost of Lost Leisure Time | C25: 3.7064031 | D25: 7.176153 | E25: -27.496971 | G25: 0.9 | H25: 258.81909 | I25: 378.26818 | J25: =(I25-I26)/I26 -> -0.070653192 | L25: 0.9 | M25: =0.9*M26 -> 275.32404 | N25: 447.85384 | O25: =(N25-N26)/N26 -> -0.0639395 | Q25: 0.9 | R25: =0.9*R26 -> 303.01253 | S25: 660.82437 | T25: =(S25-S26)/S26 -> -0.048478655
B26: Value of Higher Education | C26: 1.56 | D26: 3.14 | E26: 5.38 | G26: 1 | H26: 287.57676 | I26: 407.02586 | J26: 0 | L26: 1 | M26: 305.9156 | N26: 478.4454 | O26: 0 | Q26: 1 | R26: 336.68059 | S26: 694.49243 | T26: 0
B27: Services of Highways and Streets | G27: 1.1 | H27: 316.33444 | I27: 435.78354 | J27: =(I27-I26)/I26 -> 0.070653192 | L27: 1.1 | M27: =1.1*M26 -> 336.50716 | N27: 509.03696 | O27: =(N27-N26)/N26 -> 0.0639395 | Q27: 1.1 | R27: =1.1*R26 -> 370.34865 | S27: 728.16049 | T27: =(S27-S26)/S26 -> 0.048478655
B28: Cost of Commuting | C28: 136.24 | D28: 174.78 | E28: 212.29 | G28: 1.2 | H28: 345.09212 | I28: 464.54121 | J28: =(I28-I26)/I26 -> 0.14130638 | L28: 1.2 | M28: =1.2*M26 -> 367.09872 | N28: 539.62852 | O28: =(N28-N26)/N26 -> 0.127879 | Q28: 1.2 | R28: =1.2*R26 -> 404.01671 | S28: 761.82855 | T28: =(S28-S26)/S26 -> 0.09695731
B29: Cost of Motor Vehicle Crashes | C29: 15.1179 | D29: 14.1314 | E29: 14.493
B30: YEAR | C30: 1990 | D30: 2000 | E30: 2010
B31: Economic Elements | C31: 450.14687 | D31: 588.77157 | E31: =E6+E7-E8-E9+E10 -> 803.60193
B32: Percent Change from Previous Year | C32: 0.02686313 | D32: 0.024519618 | E32: =(E31-D31)/D31 -> 0.36487897
B33: Environmental Elements | C33: -282.61883 | D33: -302.48065 | E33: =E18-E19-E20-E21+E22+E24-E23+E25-E26-E27 -> -382.01561
B34: Percent Change from Previous Year | C34: 0.022059192 | D34: -0.0082787777 | E34: =(E33-D33)/D33 -> 0.2629423
B35: Social Elements | C35: 152.87399 | D35: 139.57683 | E35: =E20-E21-E22-E23+E24+E26-E25+E27-E28-E29 -> 182.2365
B36: Percent Change from Previous Year | C36: 0.063353588 | D36: -0.05981642 | E36: =(E35-D35)/D35 -> 0.30563575
B37: Genuine Progress Indicator | C37: 320.40203 | D37: 425.86775 | E37: =E31+E33+E35 -> 603.82282
B38: Genuine Progress Indicator - Double Check | C38: 86.623827 | D38: 52.577654 | E38: =E3-E37 -> 90.669613
B40: GDP (Adjusted for 2012$) | C40: 684.86949 | D40: 903.94528 | E40: 1337.1796
B41: GDP: Percent Change from Previous Year | C41: 0.027904779 | D41: 0.007014935 | E41: =(E40-D40)/D40 -> 0.47927048
...

Sheet Lawn comparison
A1: Year | B1: 1962 | C1: 1963 | D1: 1964 | E1: 1965 | F1: 1966 | G1: 1967 | H1: 1968 | I1: 1969 | J1: 1970 | K1: 1971 | L1: 1972 | M1: 1973 | N1: 1974 | O1: 1975 | P1: 1976 | Q1: 1977 | R1: 1978 | S1: 1979 | T1: 1980 | U1: 1981 | V1: 1982 | W1: 1983 | X1: 1984 | Y1: 1985 | Z1: 1986 | AA1: 1987 | AB1: 1988 | AC1: 1989 | AD1: 1990 | AE1: 1991 | AF1: 1992 | AG1: 1993 | AH1: 1994 | AI1: 1995 | AJ1: 1996 | AK1: 1997 | AL1: 1998 | AM1: 1999 | AN1: 2000 | AO1: 2001 | AP1: 2002 | AQ1: 2003 | AR1: 2004 | AS1: 2005 | AT1: 2006 | AU1: 2007 | AV1: 2008 | AW1: 2009 | AX1: 2010 | AY1: 2011 | AZ1: 2012 | BA1: 2013
A2: Lawn Study
A3: CPI | B3: 7.8 | C3: 7.9 | D3: 8.2 | E3: 8.5 | F3: 8.7 | G3: 9 | H3: 9.2 | I3: 9.5 | J3: 10 | K3: 10.7 | L3: 11.2 | M3: 12.6 | N3: 14.7 | O3: 16.8 | P3: 19.2 | Q3: 21 | R3: 22.6 | S3: 24.9 | T3: 27.2 | U3: 30.2 | V3: 33.6 | W3: 36.5 | X3: 37.4 | Y3: 40.5 | Z3: 44.4 | AA3: 47.6 | AB3: 51.2 | AC3: 55.2 | AD3: 59 | AE3: 59.9 | AF3: 60.1 | AG3: 61.2 | AH3: 62.8 | AI3: 66 | AJ3: 67 | AK3: 66.8 | AL3: 67.8 | AM3: 69.1 | AN3: 73.1 | AO3: 75.4 | AP3: 77.6 | AQ3: 79.5 | AR3: 81.5 | AS3: 83.8 | AT3: 86.6 | AU3: 89.1 | AV3: 92.4 | AW3: 94.3 | AX3: 96.9 | AY3: 99.8 | AZ3: 102
A4: GPI $m | B4: 303610.53 | C4: 311425.38 | D4: 321174.93 | E4: 328972.4 | F4: 333947.8 | G4: 343459.57 | H4: 354668.26 | I4: 362752.22 | J4: 374047.96 | K4: 381288.63 | L4: 392123.17 | M4: 406232.9 | N4: 418642.12 | O4: 413088.22 | P4: 409075.75 | Q4: 402300.69 | R4: 394030.19 | S4: 387971.07 | T4: 388053.97 | U4: 390160.36 | V4: 392339.58 | W4: 393813.19 | X4: 395531.43 | Y4: 404694.3 | Z4: 404905.52 | AA4: 392055.72 | AB4: 404552.22 | AC4: 404388.67 | AD4: 413621.1 | AE4: 416608.56 | AF4: 417195.77 | AG4: 416897.37 | AH4: 426171.84 | AI4: 439973.62 | AJ4: 458077.54 | AK4: 463922.46 | AL4: 465012.46 | AM4: 475090.02 | AN4: 486947.06 | AO4: 498009.37 | AP4: 510124.85 | AQ4: 513057.14 | AR4: 539262.29 | AS4: 538984.5 | AT4: 550002.54 | AU4: 545446.71 | AV4: 555917.62 | AW4: 567976.54 | AX4: 580518.16
A5: Nom $ | B5: 28259.691 | C5: 29358.717 | D5: 31427.618 | E5: 33368.322 | F5: 34669.998 | G5: 36887.066 | H5: 38937.327 | I5: 41123.461 | J5: 44635.795 | K5: 48684.825 | L5: 52407.87 | M5: 61080.364 | N5: 73437.222 | O5: 82814.822 | P5: 93726.186 | Q5: 100815.21 | R5: 106265.9 | S5: 115280.19 | T5: 125955.46 | U5: 140606.72 | V5: 157310.38 | W5: 171529.61 | X5: 176525.96 | Y5: 195586.15 | Z5: 214532.28 | AA5: 222695.14 | AB5: 247172.72 | AC5: 266375.35 | AD5: 291212.95 | AE5: 297790.61 | AF5: 299206.04 | AG5: 304464.43 | AH5: 319374.6 | AI5: 346518.6 | AJ5: 366243.38 | AK5: 369809.32 | AL5: 376227.26 | AM5: 391750.84 | AN5: 424771.24 | AO5: 448089.58 | AP5: 472382.92 | AQ5: 486730.82 | AR5: 524461.54 | AS5: 538984.5 | AT5: 568379.71 | AU5: 579943.93 | AV5: 612968.83 | AW5: 639143.06 | AX5: 671267.42
A6: Lawn 2005 GPI | B6: 362.30373 | C6: 371.62933 | D6: 383.26364 | E6: 392.56849 | F6: 398.50573 | G6: 409.85629 | H6: 423.23182 | I6: 432.87854 | J6: 446.35795 | K6: 454.99837 | L6: 467.92741 | M6: 484.7648 | N6: 499.57294 | O6: 492.94537 | P6: 488.15722 | Q6: 480.07242 | R6: 470.20309 | S6: 462.97264 | T6: 463.07156 | U6: 465.58515 | V6: 468.18566 | W6: 469.94414 | X6: 471.99455 | Y6: 482.92876 | Z6: 483.18081 | AA6: 467.84692 | AB6: 482.75921 | AC6: 482.56404 | AD6: 493.58126 | AE6: 497.14625 | AF6: 497.84698 | AG6: 497.49089 | AH6: 508.55828 | AI6: 525.02819 | AJ6: 546.63191 | AK6: 553.60676 | AL6: 554.90747 | AM6: 566.9332 | AN6: 581.08241 | AO6: 594.28326 | AP6: 608.74087 | AQ6: 612.24002 | AR6: 643.51109 | AS6: 643.1796 | AT6: 656.32762 | AU6: 650.89106 | AV6: 663.38618 | AW6: 677.77631 | AX6: 692.74244
A8: GDP $m | B8: 185636.84 | C8: 197801.42 | D8: 212774.46 | E8: 225615.78 | F8: 232844.79 | G8: 245464 | H8: 258101 | I8: 276259 | J8: 296031 | K8: 307920 | L8: 320073 | M8: 328598 | N8: 341871 | O8: 345961 | P8: 355317 | Q8: 367620 | R8: 370917 | S8: 386460 | T8: 398578 | U8: 412068 | V8: 425137 | W8: 415056 | X8: 434458 | Y8: 457594 | Z8: 477932 | AA8: 489481 | AB8: 514739 | AC8: 533794 | AD8: 554819 | AE8: 551261 | AF8: 551722 | AG8: 571887 | AH8: 595360 | AI8: 622057 | AJ8: 647659 | AK8: 673099 | AL8: 703258 | AM8: 739629 | AN8: 769045 | AO8: 784017 | AP8: 813542 | AQ8: 839187 | AR8: 873197 | AS8: 896568 | AT8: 921747 | AU8: 952164.76 | AV8: 988090.75 | AW8: 1001589.9 | AX8: 1024924.1
A9: Nom $ | B9: 17278.846 | C9: 18647.151 | D9: 20820.413 | E9: 22884.655 | F9: 24173.623 | G9: 26362.482 | H9: 28335.671 | I9: 31318.144 | J9: 35325.895 | K9: 39316.754 | L9: 42778.253 | M9: 49407.337 | N9: 59970.211 | O9: 69357.337 | P9: 81409.146 | Q9: 92124.344 | R9: 100032.51 | S9: 114831.19 | T9: 129371.38 | U9: 148501.83 | V9: 170460.66 | W9: 180782.15 | X9: 193898.92 | Y9: 221152.23 | Z9: 253224.11 | AA9: 278034.55 | AB9: 314494.47 | AC9: 351616.1 | AD9: 390624.36 | AE9: 394039.78 | AF9: 395686.06 | AG9: 417654.95 | AH9: 446164.77 | AI9: 489925.56 | AJ9: 517818.05 | AK9: 536551.47 | AL9: 568984.4 | AM9: 609885.01 | AN9: 670849.52 | AO9: 705428.18 | AP9: 753351.54 | AQ9: 796126.09 | AR9: 849230.97 | AS9: 896568 | AT9: 952545.23 | AU9: 1012385.2 | AV9: 1089493.9 | AW9: 1127087.5 | AX9: 1185144.9
A10: Lawn 2005 GDP | B10: 221.52367 | C10: 236.03988 | D10: 253.90747 | E10: 269.23124 | F10: 277.85774 | G10: 292.91647 | H10: 307.99642 | I10: 329.66468 | J10: 353.25895 | K10: 367.4463 | L10: 381.94869 | M10: 392.12172 | N10: 407.96062 | O10: 412.84129 | P10: 424.00597 | Q10: 438.68735 | R10: 442.62172 | S10: 461.16945 | T10: 475.63007 | U10: 491.72792 | V10: 507.32339 | W10: 495.29356 | X10: 518.4463 | Y10: 546.05489 | Z10: 570.32458 | AA10: 584.10621 | AB10: 614.24702 | AC10: 636.98568 | AD10: 662.07518 | AE10: 657.82936 | AF10: 658.37947 | AG10: 682.44272 | AH10: 710.45346 | AI10: 742.31146 | AJ10: 772.86277 | AK10: 803.22076 | AL10: 839.21002 | AM10: 882.61217 | AN10: 917.7148 | AO10: 935.58115 | AP10: 970.81384 | AQ10: 1001.4165 | AR10: 1042.0012 | AS10: 1069.8902 | AT10: 1099.9368 | AU10: 1136.2348 | AV10: 1179.1059 | AW10: 1195.2147 | AX10: 1223.0598
A13: ANU Study
A14: ANU 2015 GPI | B14: 202.94 | C14: 200.3 | D14: 202.16 | E14: 205.05 | F14: 209.02 | G14: 215.81 | H14: 222.26 | I14: 230.7 | J14: 239.9 | K14: 244.91 | L14: 246.45 | M14: 250.75 | N14: 257.87 | O14: 265.59 | P14: 272.7 | Q14: 268 | R14: 276.07 | S14: 277.34 | T14: 255.06 | U14: 263.87 | V14: 261.08 | W14: 266.03 | X14: 264.84 | Y14: 263.13 | Z14: 268.6 | AA14: 267.02 | AB14: 273.05 | AC14: 269.75 | AD14: 271.82 | AE14: 271.5 | AF14: 272.21 | AG14: 273.41 | AH14: 275.79 | AI14: 272.3 | AJ14: 282.67 | AK14: 294.76 | AL14: 291.7 | AM14: 304.56 | AN14: 307.02 | AO14: 330.09 | AP14: 341.25 | AQ14: 356.72 | AR14: 371.01 | AS14: 385.94 | AT14: 402.54 | AU14: 416.93 | AV14: 436.82 | AW14: 433.54 | AX14: 481.06 | AY14: 510.28 | AZ14: 526.76 | BA14: 553.56
A15: Year | B15: 1962 | C15: 1963 | D15: 1964 | E15: 1965 | F15: 1966 | G15: 1967 | H15: 1968 | I15: 1969 | J15: 1970 | K15: 1971 | L15: 1972 | M15: 1973 | N15: 1974 | O15: 1975 | P15: 1976 | Q15: 1977 | R15: 1978 | S15: 1979 | T15: 1980 | U15: 1981 | V15: 1982 | W15: 1983 | X15: 1984 | Y15: 1985 | Z15: 1986 | AA15: 1987 | AB15: 1988 | AC15: 1989 | AD15: 1990 | AE15: 1991 | AF15: 1992 | AG15: 1993 | AH15: 1994 | AI15: 1995 | AJ15: 1996 | AK15: 1997 | AL15: 1998 | AM15: 1999 | AN15: 2000 | AO15: 2001 | AP15: 2002 | AQ15: 2003 | AR15: 2004 | AS15: 2005 | AT15: 2006 | AU15: 2007 | AV15: 2008 | AW15: 2009 | AX15: 2010 | AY15: 2011 | AZ15: 2012 | BA15: 2013
A16: ANU 2015 GPI (plus $200bn) | B16: 402.94 | C16: 400.3 | D16: 402.16 | E16: 405.05 | F16: 409.02 | G16: 415.81 | H16: 422.26 | I16: 430.7 | J16: 439.9 | K16: 444.91 | L16: 446.45 | M16: 450.75 | N16: 457.87 | O16: 465.59 | P16: 472.7 | Q16: 468 | R16: 476.07 | S16: 477.34 | T16: 455.06 | U16: 463.87 | V16: 461.08 | W16: 466.03 | X16: 464.84 | Y16: 463.13 | Z16: 468.6 | AA16: 467.02 | AB16: 473.05 | AC16: 469.75 | AD16: 471.82 | AE16: 471.5 | AF16: 472.21 | AG16: 473.41 | AH16: 475.79 | AI16: 472.3 | AJ16: 482.67 | AK16: 494.76 | AL16: 491.7 | AM16: 504.56 | AN16: 507.02 | AO16: 530.09 | AP16: 541.25 | AQ16: 556.72 | AR16: 571.01 | AS16: 585.94 | AT16: 602.54 | AU16: 616.93 | AV16: 636.82 | AW16: 633.54 | AX16: 681.06 | AY16: 710.28 | AZ16: 726.76 | BA16: 753.56
A17: ANU 2015 GDP | B17: 227.65 | C17: 243 | D17: 259 | E17: 272.39 | F17: 279.72 | G17: 301.43 | H17: 316.86 | I17: 344.12 | J17: 368.34 | K17: 376.58 | L17: 396.95 | M17: 394.59 | N17: 409.82 | O17: 423.24 | P17: 433.15 | Q17: 457.14 | R17: 463.85 | S17: 475.88 | T17: 493.89 | U17: 503.54 | V17: 522.43 | W17: 517.94 | X17: 570.5 | Y17: 580.12 | Z17: 586.11 | AA17: 600.39 | AB17: 632.94 | AC17: 666.28 | AD17: 684.87 | AE17: 692.65 | AF17: 703.84 | AG17: 725.62 | AH17: 743.18 | AI17: 750.99 | AJ17: 789.64 | AK17: 833.32 | AL17: 868.33 | AM17: 897.65 | AN17: 903.95 | AO17: 935.38 | AP17: 970.99 | AQ17: 1007.42 | AR17: 1057.15 | AS17: 1100.57 | AT17: 1152.39 | AU17: 1220.01 | AV17: 1275.35 | AW17: 1334.12 | AX17: 1337.18 | AY17: 1410.69 | AZ17: 1458.85 | BA17: 1451.28

Sheet Economic Indicators per capita
A62: per capita
B63: YEAR | C63: 1962 | D63: 1963 | E63: 1964 | F63: 1965 | G63: 1966 | H63: 1967 | I63: 1968 | J63: 1969 | K63: 1970 | L63: 1971 | M63: 1972 | N63: 1973 | O63: 1974 | P63: 1975 | Q63: 1976 | R63: 1977 | S63: 1978 | T63: 1979 | U63: 1980 | V63: 1981 | W63: 1982 | X63: 1983 | Y63: 1984 | Z63: 1985 | AA63: 1986 | AB63: 1987 | AC63: 1988 | AD63: 1989 | AE63: 1990 | AF63: 1991 | AG63: 1992 | AH63: 1993 | AI63: 1994 | AJ63: 1995 | AK63: 1996 | AL63: 1997 | AM63: 1998 | AN63: 1999 | AO63: 2000 | AP63: 2001 | AQ63: 2002 | AR63: 2003 | AS63: 2004 | AT63: 2005 | AU63: 2006 | AV63: 2007 | AW63: 2008 | AX63: 2009 | AY63: 2010 | AZ63: 2011 | BA63: 2012 | BB63: 2013 | BD63: operation | BF63: % Change
A64: 1 | B64: Personal Consumption Expenditures | C64: =(Australia!C4/(Australia!C46)*1000000) -> 13009.682 | D64: =(Australia!D4/(Australia!D46)*1000000) -> 13636.53 | E64: =(Australia!E4/(Australia!E46)*1000000) -> 14113.907 | F64: =(Australia!F4/(Australia!F46)*1000000) -> 14377.415 | G64: =(Australia!G4/(Australia!G46)*1000000) -> 14602.121 | H64: =(Australia!H4/(Australia!H46)*1000000) -> 15091.109 | I64: =(Australia!I4/(Australia!I46)*1000000) -> 15720.709 | J64: =(Australia!J4/(Australia!J46)*1000000) -> 16406.263 | ... BB64: =(Australia!BB4/(Australia!BB46)*1000000) -> 36104.867
A65: 2 | B65: Income Inequality | C65: =(Australia!C5) -> 1.182 | D65: =(Australia!D5) -> 1.185 | E65: =(Australia!E5) -> 1.17 | F65: =(Australia!F5) -> 1.147 | G65: =(Australia!G5) -> 1.129 | H65: =(Australia!H5) -> 1.118 | I65: =(Australia!I5) -> 1.115 | J65: =(Australia!J5) -> 1.099 | ... BB65: =(Australia!BB5) -> 1.19
A66: 3 | B66: Adjusted Personal Consumption Expenditures | C66: =(Australia!C6/Australia!C46)*1000000 -> 11944.703 | D66: =(Australia!D6/Australia!D46)*1000000 -> 12494.977 | E66: =(Australia!E6/Australia!E46)*1000000 -> 13099.31 | F66: =(Australia!F6/Australia!F46)*1000000 -> 13600.281 | G66: =(Australia!G6/Australia!G46)*1000000 -> 14038.279 | H66: =(Australia!H6/Australia!H46)*1000000 -> 14650.394 | I66: =(Australia!I6/Australia!I46)*1000000 -> 15301.857 | J66: =(Australia!J6/Australia!J46)*1000000 -> 16199.136 | ... BB66: =(Australia!BB6/Australia!BB46)*1000000 -> 33000.346
A67: 4 | B67: Services of Consumer Durables | C67: =(Australia!C7/Australia!C46)*1000000 -> 453.65854 | D67: =(Australia!D7/Australia!D46)*1000000 -> 477.36986 | E67: =(Australia!E7/Australia!E46)*1000000 -> 504.64762 | F67: =(Australia!F7/Australia!F46)*1000000 -> 533.43871 | G67: =(Australia!G7/Australia!G46)*1000000 -> 577.53255 | H67: =(Australia!H7/Australia!H46)*1000000 -> 641.42724 | I67: =(Australia!I7/Australia!I46)*1000000 -> 719.87676 | J67: =(Australia!J7/Australia!J46)*1000000 -> 809.81815 | ... BB67: =(Australia!BB7/Australia!BB46)*1000000 -> 5257.0762
A68: 5 | B68: Cost of Consumer Durables | C68: =(Australia!C8/Australia!C46)*1000000 -> 2865.5792 | D68: =(Australia!D8/Australia!D46)*1000000 -> 3007.9186 | E68: =(Australia!E8/Australia!E46)*1000000 -> 3091.6442 | F68: =(Australia!F8/Australia!F46)*1000000 -> 3037.2528 | G68: =(Australia!G8/Australia!G46)*1000000 -> 2966.9621 | H68: =(Australia!H8/Australia!H46)*1000000 -> 3053.9311 | I68: =(Australia!I8/Australia!I46)*1000000 -> 3157.9576 | J68: =(Australia!J8/Australia!J46)*1000000 -> 3318.4977 | ... BB68: =(Australia!BB8/Australia!BB46)*1000000 -> 3367.6186
A69: 6 | B69: Cost of Underemployment | C69: =(Australia!C9/Australia!C46)*1000000 -> 92.383341 | D69: =(Australia!D9/Australia!D46)*1000000 -> 92.464998 | E69: =(Australia!E9/Australia!E46)*1000000 -> 92.487181 | F69: =(Australia!F9/Australia!F46)*1000000 -> 93.693951 | G69: =(Australia!G9/Australia!G46)*1000000 -> 95.198147 | H69: =(Australia!H9/Australia!H46)*1000000 -> 97.454651 | I69: =(Australia!I9/Australia!I46)*1000000 -> 102.05848 | J69: =(Australia!J9/Australia!J46)*1000000 -> 107.91028 | ... BB69: =(Australia!BB9/Australia!BB46)*1000000 -> 1182.1092
A70: 7 | B70: Net Capital Investment | C70: =(Australia!C10/Australia!C$46)*1000000 -> 1232.5451 | D70: =(Australia!D10/Australia!D$46)*1000000 -> 1232.8767 | E70: =(Australia!E10/Australia!E$46)*1000000 -> 1232.202 | F70: =(Australia!F10/Australia!F$46)*1000000 -> 1232.8767 | G70: =(Australia!G10/Australia!G$46)*1000000 -> 1232.8649 | H70: =(Australia!H10/Australia!H$46)*1000000 -> 1232.3078 | I70: =(Australia!I10/Australia!I$46)*1000000 -> 1232.409 | J70: =(Australia!J10/Australia!J$46)*1000000 -> 1232.9772 | ... BB70: =(Australia!BB10/Australia!BB$46)*1000000 -> 4546.9871
B72: Economic Elements | C72: =(Australia!C31/Australia!C46)*1000000 -> 10672.944 | D72: =(Australia!D31/Australia!D46)*1000000 -> 11104.84 | E72: =(Australia!E31/Australia!E46)*1000000 -> 11652.029 | F72: =(Australia!F31/Australia!F46)*1000000 -> 12235.65 | G72: =(Australia!G31/Australia!G46)*1000000 -> 12786.516 | H72: =(Australia!H31/Australia!H46)*1000000 -> 13372.743 | I72: =(Australia!I31/Australia!I46)*1000000 -> 13994.127 | J72: =(Australia!J31/Australia!J46)*1000000 -> 14815.523 | ... BB72: =(Australia!BB31/Australia!BB46)*1000000 -> 38254.681
